package net.sog.core.common.machine.multiblocks;

import com.gregtechceu.gtceu.api.GTValues;
import com.gregtechceu.gtceu.api.data.RotationState;
import com.gregtechceu.gtceu.api.machine.IMachineBlockEntity;
import com.gregtechceu.gtceu.api.machine.MachineDefinition;
import com.gregtechceu.gtceu.api.machine.MetaMachine;
import com.gregtechceu.gtceu.api.machine.MultiblockMachineDefinition;
import com.gregtechceu.gtceu.api.machine.multiblock.PartAbility;
import com.gregtechceu.gtceu.api.machine.multiblock.WorkableElectricMultiblockMachine;
import com.gregtechceu.gtceu.api.pattern.FactoryBlockPattern;
import com.gregtechceu.gtceu.api.pattern.Predicates;
import com.gregtechceu.gtceu.api.registry.registrate.MachineBuilder;
import com.gregtechceu.gtceu.common.data.*;

import net.minecraft.resources.ResourceLocation;
import net.minecraftforge.registries.ForgeRegistries;
import net.sog.core.client.renderer.machine.multiblock.SoGDynamicRenderHelpers;
import net.sog.core.common.data.SoGRecipeTypes;
import net.sog.core.sogcore;

import java.util.Locale;
import java.util.function.BiFunction;

import static com.gregtechceu.gtceu.api.pattern.Predicates.*;
import static com.gregtechceu.gtceu.common.data.models.GTMachineModels.*;
import static net.sog.core.common.data.SoGBlocks.*;
import static net.sog.core.common.registry.SoGRegistration.REGISTRATE;

@SuppressWarnings("all")
public class HighEnergyCollider {

    static {
        REGISTRATE.creativeModeTab(() -> sogcore.SOG_CREATIVE_TAB);
    }

    public static final MultiblockMachineDefinition HIGH_ENERGY_COLLIDER = REGISTRATE
            .multiblock("high_energy_collider", WorkableElectricMultiblockMachine::new)
            .langValue("High-Energy Collider")
            .recipeModifiers(GTRecipeModifiers.OC_NON_PERFECT_SUBTICK, GTRecipeModifiers.PARALLEL_HATCH)
            .rotationState(RotationState.NON_Y_AXIS)
            .recipeType(SoGRecipeTypes.HIGH_ENERGY_COLLIDER_RECIPES)
            .appearanceBlock(ULTRA_DENSE_COLLIDER_CASING)
            .pattern(definition -> FactoryBlockPattern.start()
                    .aisle("AAAAAAAAAAAAAAAAAAAAAAAAAAAAAAAAAAAAAAA", "AAAAAAAAAAAAAAAAAAAAAAAAAAAAAAAAAAAAAAA",
                            "AAAAAAAAAAAAAAAAAAAAAAAAAAAAAAAAAAAAAAA", "AAAAAAAAAAAAAAAAAAAAAAAAAAAAAAAAAAAAAAA",
                            "AAAAAAAAAAAAAAAAAAAAAAAAAAAAAAAAAAAAAAA", "AAAAAAAAAAAAAAAAAAAAAAAAAAAAAAAAAAAAAAA",
                            "AAAAAAAAAAAAAAAAAAAAAAAAAAAAAAAAAAAAAAA", "AAAAAAAAAAAAAAAAAAAAAAAAAAAAAAAAAAAAAAA",
                            "AAAAAAAAAAAAAAAAAAAAAAAAAAAAAAAAAAAAAAA", "AAAAAAAAAAAAAAAAAAAAAAAAAAAAAAAAAAAAAAA",
                            "AAAAAAAAAAAAAAAAAAAAAAAAAAAAAAAAAAAAAAA", "AAAAAAAAAAAAAAAAAAAAAAAAAAAAAAAAAAAAAAA",
                            "AAAAAAAAAAAAAAAAAAAAAAAAAAAAAAAAAAAAAAA", "AAAAAAAAAAAAAAAAAAAAAAAAAAAAAAAAAAAAAAA",
                            "AAAAAAAAAAAAAAAAAAAAAAAAAAAAAAAAAAAAAAA", "AAAAAAAAAAAAAAAAAAAAAAAAAAAAAAAAAAAAAAA",
                            "AAAAAAAAAAAAAAAAAAAAAAAAAAAAAAAAAAAAAAA", "AAAAAAAAAAAAAAAAAAAAAAAAAAAAAAAAAAAAAAA",
                            "AAAAAAAAAAAAAAAAAAAAAAAAAAAAAAAAAAAAAAA", "AAAAAAAAAAAAAAAAAAABAAAAAAAAAAAAAAAAAAA",
                            "AAAAAAAAAAAAAAAAAABBBAAAAAAAAAAAAAAAAAA", "AAAAAAAAAAAAAAAAAAABAAAAAAAAAAAAAAAAAAA",
                            "AAAAAAAAAAAAAAAAAAAAAAAAAAAAAAAAAAAAAAA", "AAAAAAAAAAAAAAAAAAAAAAAAAAAAAAAAAAAAAAA",
                            "AAAAAAAAAAAAAAAAAAAAAAAAAAAAAAAAAAAAAAA", "AAAAAAAAAAAAAAAAAAAAAAAAAAAAAAAAAAAAAAA",
                            "AAAAAAAAAAAAAAAAAAAAAAAAAAAAAAAAAAAAAAA", "AAAAAAAAAAAAAAAAAAAAAAAAAAAAAAAAAAAAAAA",
                            "AAAAAAAAAAAAAAAAAAAAAAAAAAAAAAAAAAAAAAA", "AAAAAAAAAAAAAAAAAAAAAAAAAAAAAAAAAAAAAAA",
                            "AAAAAAAAAAAAAAAAAAAAAAAAAAAAAAAAAAAAAAA", "AAAAAAAAAAAAAAAAAAAAAAAAAAAAAAAAAAAAAAA",
                            "AAAAAAAAAAAAAAAAAAAAAAAAAAAAAAAAAAAAAAA", "AAAAAAAAAAAAAAAAAAAAAAAAAAAAAAAAAAAAAAA",
                            "AAAAAAAAAAAAAAAAAAAAAAAAAAAAAAAAAAAAAAA", "AAAAAAAAAAAAAAAAAAAAAAAAAAAAAAAAAAAAAAA",
                            "AAAAAAAAAAAAAAAAAAAAAAAAAAAAAAAAAAAAAAA", "AAAAAAAAAAAAAAAAAAAAAAAAAAAAAAAAAAAAAAA",
                            "AAAAAAAAAAAAAAAAAAAAAAAAAAAAAAAAAAAAAAA", "AAAAAAAAAAAAAAAAAAAAAAAAAAAAAAAAAAAAAAA")
                    .aisle("AAAAAAAAAAAAAAAAAAAAAAAAAAAAAAAAAAAAAAA", "AAAAAAAAAAAAAAAAAAAAAAAAAAAAAAAAAAAAAAA",
                            "AAAAAAAAAAAAAAAAAAAAAAAAAAAAAAAAAAAAAAA", "AAAAAAAAAAAAAAAAAAAAAAAAAAAAAAAAAAAAAAA",
                            "AAAAAAAAAAAAAAAAAAAAAAAAAAAAAAAAAAAAAAA", "AAAAAAAAAAAAAAAAAAAAAAAAAAAAAAAAAAAAAAA",
                            "AAAAAAAAAAAAAAAAAAAAAAAAAAAAAAAAAAAAAAA", "AAAAAAAAAAAAAAAAAAAAAAAAAAAAAAAAAAAAAAA",
                            "AAAAAAAAAAAAAAAAAAAAAAAAAAAAAAAAAAAAAAA", "AAAAAAAAAAAAAAAAAAAAAAAAAAAAAAAAAAAAAAA",
                            "AAAAAAAAAAAAAAAAAAAAAAAAAAAAAAAAAAAAAAA", "AAAAAAAAAAAAAAAAAAAAAAAAAAAAAAAAAAAAAAA",
                            "AAAAAAAAAAAAAAAAAAAAAAAAAAAAAAAAAAAAAAA", "AAAAAAAAAAAAAAAAAAAAAAAAAAAAAAAAAAAAAAA",
                            "AAAAAAAAAAAAAAAAAAAAAAAAAAAAAAAAAAAAAAA", "AAAAAAAAAAAAAAAAAAADAAAAAAAAAAAAAAAAAAA",
                            "AAAAAAAAAAAAAAAAAAADAAAAAAAAAAAAAAAAAAA", "AAAAAAAAAAAAAAAAAAADAAAAAAAAAAAAAAAAAAA",
                            "AAAAAAAAAAAAAAAAAADDDAAAAAAAAAAAAAAAAAA", "AAAAAAAAAAAAAAAAADDEDDAAAAAAAAAAAAAAAAA",
                            "AAAAAAAAAAAAAABBBDEEEDBBBAAAAAAAAAAAAAA", "AAAAAAAAAAAAAADDDDDEDDDDDAAAAAAAAAAAAAA",
                            "AAAAAAAAAAAAAAAAAADDDAAAAAAAAAAAAAAAAAA", "AAAAAAAAAAAAAAAAAAADAAAAAAAAAAAAAAAAAAA",
                            "AAAAAAAAAAAAAAAAAAADAAAAAAAAAAAAAAAAAAA", "AAAAAAAAAAAAAAAAAAADAAAAAAAAAAAAAAAAAAA",
                            "AAAAAAAAAAAAAAAAAAADAAAAAAAAAAAAAAAAAAA", "AAAAAAAAAAAAAAAAAAAAAAAAAAAAAAAAAAAAAAA",
                            "AAAAAAAAAAAAAAAAAAAAAAAAAAAAAAAAAAAAAAA", "AAAAAAAAAAAAAAAAAAAAAAAAAAAAAAAAAAAAAAA",
                            "AAAAAAAAAAAAAAAAAAAAAAAAAAAAAAAAAAAAAAA", "AAAAAAAAAAAAAAAAAAAAAAAAAAAAAAAAAAAAAAA",
                            "AAAAAAAAAAAAAAAAAAAAAAAAAAAAAAAAAAAAAAA", "AAAAAAAAAAAAAAAAAAAAAAAAAAAAAAAAAAAAAAA",
                            "AAAAAAAAAAAAAAAAAAAAAAAAAAAAAAAAAAAAAAA", "AAAAAAAAAAAAAAAAAAAAAAAAAAAAAAAAAAAAAAA",
                            "AAAAAAAAAAAAAAAAAAAAAAAAAAAAAAAAAAAAAAA", "AAAAAAAAAAAAAAAAAAAAAAAAAAAAAAAAAAAAAAA",
                            "AAAAAAAAAAAAAAAAAAAAAAAAAAAAAAAAAAAAAAA", "AAAAAAAAAAAAAAAAAAAAAAAAAAAAAAAAAAAAAAA")
                    .aisle("AAAAAAAAAAAAAAAAAAAAAAAAAAAAAAAAAAAAAAA", "AAAAAAAAAAAAAAAAAAAAAAAAAAAAAAAAAAAAAAA",
                            "AAAAAAAAAAAAAAAAAAAAAAAAAAAAAAAAAAAAAAA", "AAAAAAAAAAAAAAAAAAAAAAAAAAAAAAAAAAAAAAA",
                            "AAAAAAAAAAAAAAAAAAAAAAAAAAAAAAAAAAAAAAA", "AAAAAAAAAAAAAAAAAAAAAAAAAAAAAAAAAAAAAAA",
                            "AAAAAAAAAAAAAAAAAAAAAAAAAAAAAAAAAAAAAAA", "AAAAAAAAAAAAAAAAAAAAAAAAAAAAAAAAAAAAAAA",
                            "AAAAAAAAAAAAAAAAAAAAAAAAAAAAAAAAAAAAAAA", "AAAAAAAAAAAAAAAAAAAAAAAAAAAAAAAAAAAAAAA",
                            "AAAAAAAAAAAAAAAAAAAAAAAAAAAAAAAAAAAAAAA", "AAAAAAAAAAAAAAAAAAAAAAAAAAAAAAAAAAAAAAA",
                            "AAAAAAAAAAAAAAAAAAAAAAAAAAAAAAAAAAAAAAA", "AAAAAAAAAAAAAAAAAAAAAAAAAAAAAAAAAAAAAAA",
                            "AAAAAAAAAAAAAAAAAAAAAAAAAAAAAAAAAAAAAAA", "AAAAAAAAAAAAAAAAAAAAAAAAAAAAAAAAAAAAAAA",
                            "AAAAAAAAAAAAAAAAAAAAAAAAAAAAAAAAAAAAAAA", "AAAAAAAAAAAAAAAAAAAAAAAAAAAAAAAAAAAAAAA",
                            "AAAAAAAAAAAAAAAAAAAAAAAAAAAAAAAAAAAAAAA", "AAAAAAAAAAAAAADDDDDDDDDDDAAAAAAAAAAAAAA",
                            "AAAAAAAAAAABBBEEEDEEEDEEEBBBAAAAAAAAAAA", "AAAAAAAAAAAAAADDDDDDDDDDDAAAAAAAAAAAAAA",
                            "AAAAAAAAAAAAAAAAAAAAAAAAAAAAAAAAAAAAAAA", "AAAAAAAAAAAAAAAAAAAAAAAAAAAAAAAAAAAAAAA",
                            "AAAAAAAAAAAAAAAAAAAAAAAAAAAAAAAAAAAAAAA", "AAAAAAAAAAAAAAAAAAAAAAAAAAAAAAAAAAAAAAA",
                            "AAAAAAAAAAAAAAAAAAAAAAAAAAAAAAAAAAAAAAA", "AAAAAAAAAAAAAAAAAAAAAAAAAAAAAAAAAAAAAAA",
                            "AAAAAAAAAAAAAAAAAAAAAAAAAAAAAAAAAAAAAAA", "AAAAAAAAAAAAAAAAAAAAAAAAAAAAAAAAAAAAAAA",
                            "AAAAAAAAAAAAAAAAAAAAAAAAAAAAAAAAAAAAAAA", "AAAAAAAAAAAAAAAAAAAAAAAAAAAAAAAAAAAAAAA",
                            "AAAAAAAAAAAAAAAAAAAAAAAAAAAAAAAAAAAAAAA", "AAAAAAAAAAAAAAAAAAAAAAAAAAAAAAAAAAAAAAA",
                            "AAAAAAAAAAAAAAAAAAAAAAAAAAAAAAAAAAAAAAA", "AAAAAAAAAAAAAAAAAAAAAAAAAAAAAAAAAAAAAAA",
                            "AAAAAAAAAAAAAAAAAAAAAAAAAAAAAAAAAAAAAAA", "AAAAAAAAAAAAAAAAAAAAAAAAAAAAAAAAAAAAAAA",
                            "AAAAAAAAAAAAAAAAAAAAAAAAAAAAAAAAAAAAAAA", "AAAAAAAAAAAAAAAAAAAAAAAAAAAAAAAAAAAAAAA")
                    .aisle("AAAAAAAAAAAAAAAAAAAAAAAAAAAAAAAAAAAAAAA", "AAAAAAAAAAAAAAAAAAAAAAAAAAAAAAAAAAAAAAA",
                            "AAAAAAAAAAAAAAAAAAAAAAAAAAAAAAAAAAAAAAA", "AAAAAAAAAAAAAAAAAAAAAAAAAAAAAAAAAAAAAAA",
                            "AAAAAAAAAAAAAAAAAAAAAAAAAAAAAAAAAAAAAAA", "AAAAAAAAAAAAAAAAAAAAAAAAAAAAAAAAAAAAAAA",
                            "AAAAAAAAAAAAAAAAAAAAAAAAAAAAAAAAAAAAAAA", "AAAAAAAAAAAAAAAAAAAAAAAAAAAAAAAAAAAAAAA",
                            "AAAAAAAAAAAAAAAAAAAAAAAAAAAAAAAAAAAAAAA", "AAAAAAAAAAAAAAAAAAAAAAAAAAAAAAAAAAAAAAA",
                            "AAAAAAAAAAAAAAAAAAAAAAAAAAAAAAAAAAAAAAA", "AAAAAAAAAAAAAAAAAAAAAAAAAAAAAAAAAAAAAAA",
                            "AAAAAAAAAAAAAAAAAAAAAAAAAAAAAAAAAAAAAAA", "AAAAAAAAAAAAAAAAAAAAAAAAAAAAAAAAAAAAAAA",
                            "AAAAAAAAAAAAAAAAAAAAAAAAAAAAAAAAAAAAAAA", "AAAAAAAAAAAAAAAAAAAAAAAAAAAAAAAAAAAAAAA",
                            "AAAAAAAAAAAAAAAAAAAAAAAAAAAAAAAAAAAAAAA", "AAAAAAAAAAAAAAAAAAAAAAAAAAAAAAAAAAAAAAA",
                            "AAAAAAAAAAAAAAAAAAAAAAAAAAAAAAAAAAAAAAA", "AAAAAAAAAAADDDAAAAAAAAAAADDDAAAAAAAAAAA",
                            "AAAAAAAAABBEEEAAAAAAAAAAAEEEBBAAAAAAAAA", "AAAAAAAAAAADDDAAAAAAAAAAADDDAAAAAAAAAAA",
                            "AAAAAAAAAAAAAAAAAAAAAAAAAAAAAAAAAAAAAAA", "AAAAAAAAAAAAAAAAAAAAAAAAAAAAAAAAAAAAAAA",
                            "AAAAAAAAAAAAAAAAAAAAAAAAAAAAAAAAAAAAAAA", "AAAAAAAAAAAAAAAAAAAAAAAAAAAAAAAAAAAAAAA",
                            "AAAAAAAAAAAAAAAAAAAAAAAAAAAAAAAAAAAAAAA", "AAAAAAAAAAAAAAAAAAAAAAAAAAAAAAAAAAAAAAA",
                            "AAAAAAAAAAAAAAAAAAAAAAAAAAAAAAAAAAAAAAA", "AAAAAAAAAAAAAAAAAAAAAAAAAAAAAAAAAAAAAAA",
                            "AAAAAAAAAAAAAAAAAAAAAAAAAAAAAAAAAAAAAAA", "AAAAAAAAAAAAAAAAAAAAAAAAAAAAAAAAAAAAAAA",
                            "AAAAAAAAAAAAAAAAAAAAAAAAAAAAAAAAAAAAAAA", "AAAAAAAAAAAAAAAAAAAAAAAAAAAAAAAAAAAAAAA",
                            "AAAAAAAAAAAAAAAAAAAAAAAAAAAAAAAAAAAAAAA", "AAAAAAAAAAAAAAAAAAAAAAAAAAAAAAAAAAAAAAA",
                            "AAAAAAAAAAAAAAAAAAAAAAAAAAAAAAAAAAAAAAA", "AAAAAAAAAAAAAAAAAAAAAAAAAAAAAAAAAAAAAAA",
                            "AAAAAAAAAAAAAAAAAAAAAAAAAAAAAAAAAAAAAAA", "AAAAAAAAAAAAAAAAAAAAAAAAAAAAAAAAAAAAAAA")
                    .aisle("AAAAAAAAAAAAAAAAAAAAAAAAAAAAAAAAAAAAAAA", "AAAAAAAAAAAAAAAAAAAAAAAAAAAAAAAAAAAAAAA",
                            "AAAAAAAAAAAAAAAAAAAAAAAAAAAAAAAAAAAAAAA", "AAAAAAAAAAAAAAAAAAAAAAAAAAAAAAAAAAAAAAA",
                            "AAAAAAAAAAAAAAAAAAAAAAAAAAAAAAAAAAAAAAA", "AAAAAAAAAAAAAAAAAAAAAAAAAAAAAAAAAAAAAAA",
                            "AAAAAAAAAAAAAAAAAAAAAAAAAAAAAAAAAAAAAAA", "AAAAAAAAAAAAAAAAAAAAAAAAAAAAAAAAAAAAAAA",
                            "AAAAAAAAAAAAAAAAAAAAAAAAAAAAAAAAAAAAAAA", "AAAAAAAAAAAAAAAAAAAAAAAAAAAAAAAAAAAAAAA",
                            "AAAAAAAAAAAAAAAAAAAAAAAAAAAAAAAAAAAAAAA", "AAAAAAAAAAAAAAAAAAAAAAAAAAAAAAAAAAAAAAA",
                            "AAAAAAAAAAAAAAAAAAAAAAAAAAAAAAAAAAAAAAA", "AAAAAAAAAAAAAAAAAAAAAAAAAAAAAAAAAAAAAAA",
                            "AAAAAAAAAAAAAAAAAAAAAAAAAAAAAAAAAAAAAAA", "AAAAAAAAAAAAAAAAAAAAAAAAAAAAAAAAAAAAAAA",
                            "AAAAAAAAAAAAAAAAAAAAAAAAAAAAAAAAAAAAAAA", "AAAAAAAAAAAAAAAAAAAAAAAAAAAAAAAAAAAAAAA",
                            "AAAAAAAAAAAAAAAAAAAAAAAAAAAAAAAAAAAAAAA", "AAAAAAAAADDAAAAAAAAAAAAAAAAADDAAAAAAAAA",
                            "AAAAAAAABEEAAAAAAAAAAAAAAAAAEEBAAAAAAAA", "AAAAAAAAADDAAAAAAAAAAAAAAAAADDAAAAAAAAA",
                            "AAAAAAAAAAAAAAAAAAAAAAAAAAAAAAAAAAAAAAA", "AAAAAAAAAAAAAAAAAAAAAAAAAAAAAAAAAAAAAAA",
                            "AAAAAAAAAAAAAAAAAAAAAAAAAAAAAAAAAAAAAAA", "AAAAAAAAAAAAAAAAAAAAAAAAAAAAAAAAAAAAAAA",
                            "AAAAAAAAAAAAAAAAAAAAAAAAAAAAAAAAAAAAAAA", "AAAAAAAAAAAAAAAAAAAAAAAAAAAAAAAAAAAAAAA",
                            "AAAAAAAAAAAAAAAAAAAAAAAAAAAAAAAAAAAAAAA", "AAAAAAAAAAAAAAAAAAAAAAAAAAAAAAAAAAAAAAA",
                            "AAAAAAAAAAAAAAAAAAAAAAAAAAAAAAAAAAAAAAA", "AAAAAAAAAAAAAAAAAAAAAAAAAAAAAAAAAAAAAAA",
                            "AAAAAAAAAAAAAAAAAAAAAAAAAAAAAAAAAAAAAAA", "AAAAAAAAAAAAAAAAAAAAAAAAAAAAAAAAAAAAAAA",
                            "AAAAAAAAAAAAAAAAAAAAAAAAAAAAAAAAAAAAAAA", "AAAAAAAAAAAAAAAAAAAAAAAAAAAAAAAAAAAAAAA",
                            "AAAAAAAAAAAAAAAAAAAAAAAAAAAAAAAAAAAAAAA", "AAAAAAAAAAAAAAAAAAAAAAAAAAAAAAAAAAAAAAA",
                            "AAAAAAAAAAAAAAAAAAAAAAAAAAAAAAAAAAAAAAA", "AAAAAAAAAAAAAAAAAAAAAAAAAAAAAAAAAAAAAAA")
                    .aisle("AAAAAAAAAAAAAAAAAAAAAAAAAAAAAAAAAAAAAAA", "AAAAAAAAAAAAAAAAAAAAAAAAAAAAAAAAAAAAAAA",
                            "AAAAAAAAAAAAAAAAAAAAAAAAAAAAAAAAAAAAAAA", "AAAAAAAAAAAAAAAAAAAAAAAAAAAAAAAAAAAAAAA",
                            "AAAAAAAAAAAAAAAAAAAAAAAAAAAAAAAAAAAAAAA", "AAAAAAAAAAAAAAAAAAAAAAAAAAAAAAAAAAAAAAA",
                            "AAAAAAAAAAAAAAAAAAAAAAAAAAAAAAAAAAAAAAA", "AAAAAAAAAAAAAAAAAAAAAAAAAAAAAAAAAAAAAAA",
                            "AAAAAAAAAAAAAAAAAAAAAAAAAAAAAAAAAAAAAAA", "AAAAAAAAAAAAAAAAAAAAAAAAAAAAAAAAAAAAAAA",
                            "AAAAAAAAAAAAAAAAAAAAAAAAAAAAAAAAAAAAAAA", "AAAAAAAAAAAAAAAAAAAAAAAAAAAAAAAAAAAAAAA",
                            "AAAAAAAAAAAAAAAAAAAAAAAAAAAAAAAAAAAAAAA", "AAAAAAAAAAAAAAAAAAAAAAAAAAAAAAAAAAAAAAA",
                            "AAAAAAAAAAAAAAAAAAAAAAAAAAAAAAAAAAAAAAA", "AAAAAAAAAAAAAAAAAAAAAAAAAAAAAAAAAAAAAAA",
                            "AAAAAAAAAAAAAAAAAAAAAAAAAAAAAAAAAAAAAAA", "AAAAAAADAAAAAAAAAAAAAAAAAAAAAAADAAAAAAA",
                            "AAAAAAADAAAAAAAAAAAAAAAAAAAAAAADAAAAAAA", "AAAAAAADDAAAAAAAAAAAAAAAAAAAAADDAAAAAAA",
                            "AAAAAAADEAAAAAAAAAAAAAAAAAAAAAEDAAAAAAA", "AAAAAAADDAAAAAAAAAAAAAAAAAAAAADDAAAAAAA",
                            "AAAAAAADAAAAAAAAAAAAAAAAAAAAAAADAAAAAAA", "AAAAAAADAAAAAAAAAAAAAAAAAAAAAAADAAAAAAA",
                            "AAAAAAAAAAAAAAAAAAAAAAAAAAAAAAAAAAAAAAA", "AAAAAAAAAAAAAAAAAAAAAAAAAAAAAAAAAAAAAAA",
                            "AAAAAAAAAAAAAAAAAAAAAAAAAAAAAAAAAAAAAAA", "AAAAAAAAAAAAAAAAAAAAAAAAAAAAAAAAAAAAAAA",
                            "AAAAAAAAAAAAAAAAAAAAAAAAAAAAAAAAAAAAAAA", "AAAAAAAAAAAAAAAAAAAAAAAAAAAAAAAAAAAAAAA",
                            "AAAAAAAAAAAAAAAAAAAAAAAAAAAAAAAAAAAAAAA", "AAAAAAAAAAAAAAAAAAAAAAAAAAAAAAAAAAAAAAA",
                            "AAAAAAAAAAAAAAAAAAAAAAAAAAAAAAAAAAAAAAA", "AAAAAAAAAAAAAAAAAAAAAAAAAAAAAAAAAAAAAAA",
                            "AAAAAAAAAAAAAAAAAAAAAAAAAAAAAAAAAAAAAAA", "AAAAAAAAAAAAAAAAAAAAAAAAAAAAAAAAAAAAAAA",
                            "AAAAAAAAAAAAAAAAAAAAAAAAAAAAAAAAAAAAAAA", "AAAAAAAAAAAAAAAAAAAAAAAAAAAAAAAAAAAAAAA",
                            "AAAAAAAAAAAAAAAAAAAAAAAAAAAAAAAAAAAAAAA", "AAAAAAAAAAAAAAAAAAAAAAAAAAAAAAAAAAAAAAA")
                    .aisle("AAAAAAAAAAAAAAAAAAAAAAAAAAAAAAAAAAAAAAA", "AAAAAAAAAAAAAAAAAAAAAAAAAAAAAAAAAAAAAAA",
                            "AAAAAAAAAAAAAAAAAAAAAAAAAAAAAAAAAAAAAAA", "AAAAAAAAAAAAAAAAAAAAAAAAAAAAAAAAAAAAAAA",
                            "AAAAAAAAAAAAAAAAAAAAAAAAAAAAAAAAAAAAAAA", "AAAAAAAAAAAAAAAAAAAAAAAAAAAAAAAAAAAAAAA",
                            "AAAAAAAAAAAAAAAAAAAAAAAAAAAAAAAAAAAAAAA", "AAAAAAAAAAAAAAAAAAAAAAAAAAAAAAAAAAAAAAA",
                            "AAAAAAAAAAAAAAAAAAAAAAAAAAAAAAAAAAAAAAA", "AAAAAAAAAAAAAAAAAAAAAAAAAAAAAAAAAAAAAAA",
                            "AAAAAAAAAAAAAAAAAAAAAAAAAAAAAAAAAAAAAAA", "AAAAAAAAAAAAAAAAAAAAAAAAAAAAAAAAAAAAAAA",
                            "AAAAAAAAAAAAAAAAAAAAAAAAAAAAAAAAAAAAAAA", "AAAAAAAAAAAAAAAAAAAAAAAAAAAAAAAAAAAAAAA",
                            "AAAAAADAAAAAAAAAAAAAAAAAAAAAAAAADAAAAAA", "AAAAAADAAAAAAAAAAAAAAAAAAAAAAAAADAAAAAA",
                            "AAAAAADAAAAAAAAAAAAAAAAAAAAAAAAADAAAAAA", "AAAAAADAAAAAAAAAAAAAAAAAAAAAAAAADAAAAAA",
                            "AAAAAADAAAAAAAAAAAAAAAAAAAAAAAAADAAAAAA", "AAAAAADAAAAAAAAAAAAAAAAAAAAAAAAADAAAAAA",
                            "AAAAAAAFAAAAAAAAAAAAAAAAAAAAAAAFAAAAAAA", "AAAAAADAAAAAAAAAAAAAAAAAAAAAAAAADAAAAAA",
                            "AAAAAADAAAAAAAAAAAAAAAAAAAAAAAAADAAAAAA", "AAAAAADAAAAAAAAAAAAAAAAAAAAAAAAADAAAAAA",
                            "AAAAAADAAAAAAAAAAAAAAAAAAAAAAAAADAAAAAA", "AAAAAADAAAAAAAAAAAAAAAAAAAAAAAAADAAAAAA",
                            "AAAAAADAAAAAAAAAAAAAAAAAAAAAAAAADAAAAAA", "AAAAAAAAAAAAAAAAAAAAAAAAAAAAAAAAAAAAAAA",
                            "AAAAAAAAAAAAAAAAAAAAAAAAAAAAAAAAAAAAAAA", "AAAAAAAAAAAAAAAAAAAAAAAAAAAAAAAAAAAAAAA",
                            "AAAAAAAAAAAAAAAAAAAAAAAAAAAAAAAAAAAAAAA", "AAAAAAAAAAAAAAAAAAAAAAAAAAAAAAAAAAAAAAA",
                            "AAAAAAAAAAAAAAAAAAAAAAAAAAAAAAAAAAAAAAA", "AAAAAAAAAAAAAAAAAAAAAAAAAAAAAAAAAAAAAAA",
                            "AAAAAAAAAAAAAAAAAAAAAAAAAAAAAAAAAAAAAAA", "AAAAAAAAAAAAAAAAAAAAAAAAAAAAAAAAAAAAAAA",
                            "AAAAAAAAAAAAAAAAAAAAAAAAAAAAAAAAAAAAAAA", "AAAAAAAAAAAAAAAAAAAAAAAAAAAAAAAAAAAAAAA",
                            "AAAAAAAAAAAAAAAAAAAAAAAAAAAAAAAAAAAAAAA", "AAAAAAAAAAAAAAAAAAAAAAAAAAAAAAAAAAAAAAA")
                    .aisle("AAAAAAAAAAAAAAAAAAAAAAAAAAAAAAAAAAAAAAA", "AAAAAAAAAAAAAAAAAAAAAAAAAAAAAAAAAAAAAAA",
                            "AAAAAAAAAAAAAAAAAAAAAAAAAAAAAAAAAAAAAAA", "AAAAAAAAAAAAAAAAAAAAAAAAAAAAAAAAAAAAAAA",
                            "AAAAAAAAAAAAAAAAAAAAAAAAAAAAAAAAAAAAAAA", "AAAAAAAAAAAAAAAAAAAAAAAAAAAAAAAAAAAAAAA",
                            "AAAAAAAAAAAAAAAAAAAAAAAAAAAAAAAAAAAAAAA", "AAAAAAAAAAAAAAAAAAAAAAAAAAAAAAAAAAAAAAA",
                            "AAAAAAAAAAAAAAAAAAAAAAAAAAAAAAAAAAAAAAA", "AAAAAAAAAAAAAAAAAAAAAAAAAAAAAAAAAAAAAAA",
                            "AAAAAAAAAAAAAAAAAAAAAAAAAAAAAAAAAAAAAAA", "AAAAAAAAAAAAAAAAAAAAAAAAAAAAAAAAAAAAAAA",
                            "AAAAAAAAAAAAAAAAAAAAAAAAAAAAAAAAAAAAAAA", "AAAAAAAAAAAAAAAAAAAAAAAAAAAAAAAAAAAAAAA",
                            "AAAAAAAAAAAAAAAAAAAAAAAAAAAAAAAAAAAAAAA", "AAAAAAAAAAAAAAAAAAAAAAAAAAAAAAAAAAAAAAA",
                            "AAAAAAAAAAAAAAAAAAAAAAAAAAAAAAAAAAAAAAA", "AAAAADAAAAAAAAAAAAAAAAAAAAAAAAAAADAAAAA",
                            "AAAAADAAAAAAAAAAAAAAAAAAAAAAAAAAADAAAAA", "AAAAADAAAAAAAAAAAAAAAAAAAAAAAAAAADAAAAA",
                            "AAAAADFAAAAAAAAAAAAAAAAAAAAAAAAAFDAAAAA", "AAAAADAAAAAAAAAAAAAAAAAAAAAAAAAAADAAAAA",
                            "AAAAADAAAAAAAAAAAAAAAAAAAAAAAAAAADAAAAA", "AAAAADAAAAAAAAAAAAAAAAAAAAAAAAAAADAAAAA",
                            "AAAAAAAAAAAAAAAAAAAAAAAAAAAAAAAAAAAAAAA", "AAAAAAAAAAAAAAAAAAAAAAAAAAAAAAAAAAAAAAA",
                            "AAAAAAAAAAAAAAAAAAAAAAAAAAAAAAAAAAAAAAA", "AAAAAAAAAAAAAAAAAAAAAAAAAAAAAAAAAAAAAAA",
                            "AAAAAAAAAAAAAAAAAAAAAAAAAAAAAAAAAAAAAAA", "AAAAAAAAAAAAAAAAAAAAAAAAAAAAAAAAAAAAAAA",
                            "AAAAAAAAAAAAAAAAAAAAAAAAAAAAAAAAAAAAAAA", "AAAAAAAAAAAAAAAAAAAAAAAAAAAAAAAAAAAAAAA",
                            "AAAAAAAAAAAAAAAAAAAAAAAAAAAAAAAAAAAAAAA", "AAAAAAAAAAAAAAAAAAAAAAAAAAAAAAAAAAAAAAA",
                            "AAAAAAAAAAAAAAAAAAAAAAAAAAAAAAAAAAAAAAA", "AAAAAAAAAAAAAAAAAAAAAAAAAAAAAAAAAAAAAAA",
                            "AAAAAAAAAAAAAAAAAAAAAAAAAAAAAAAAAAAAAAA", "AAAAAAAAAAAAAAAAAAAAAAAAAAAAAAAAAAAAAAA",
                            "AAAAAAAAAAAAAAAAAAAAAAAAAAAAAAAAAAAAAAA", "AAAAAAAAAAAAAAAAAAAAAAAAAAAAAAAAAAAAAAA")
                    .aisle("AAAAAAAAAAAAAAAAAAAAAAAAAAAAAAAAAAAAAAA", "AAAAAAAAAAAAAAAAAAAAAAAAAAAAAAAAAAAAAAA",
                            "AAAAAAAAAAAAAAAAAAADAAAAAAAAAAAAAAAAAAA", "AAAAAAAAAAAAAAAAAAAAAAAAAAAAAAAAAAAAAAA",
                            "AAAAAAAAAAAAAAAAAAAAAAAAAAAAAAAAAAAAAAA", "AAAAAAAAAAAAAAAAAAAAAAAAAAAAAAAAAAAAAAA",
                            "AAAAAAAAAAAAAAAAAAAAAAAAAAAAAAAAAAAAAAA", "AAAAAAAAAAAAAAAAAAAAAAAAAAAAAAAAAAAAAAA",
                            "AAAAAAAAAAAAAAAAAAAAAAAAAAAAAAAAAAAAAAA", "AAAAAAAAAAAAAAAAAAAAAAAAAAAAAAAAAAAAAAA",
                            "AAAAAAAAAAAAAAAAAAAAAAAAAAAAAAAAAAAAAAA", "AAAAAAAAAAAAAAAAAAAAAAAAAAAAAAAAAAAAAAA",
                            "AAAAAAAAAAAAAAAAAAAAAAAAAAAAAAAAAAAAAAA", "AAAAAAAAAAAAAAAAAAAAAAAAAAAAAAAAAAAAAAA",
                            "AAAAAAAAAAAAAAAAAAAAAAAAAAAAAAAAAAAAAAA", "AAAAAAAAAAAAAAAAAAAAAAAAAAAAAAAAAAAAAAA",
                            "AAAAAAAAAAAAAAAAAAAAAAAAAAAAAAAAAAAAAAA", "AAAAAAAAAAAAAAAAAAAAAAAAAAAAAAAAAAAAAAA",
                            "AAAAAAAAAAAAAAAAAAAAAAAAAAAAAAAAAAAAAAA", "AAAAADAAAAAAAAAAAAAAAAAAAAAAAAAAADAAAAA",
                            "AAAABEAAAAAAAAAAAAAAAAAAAAAAAAAAAEBAAAA", "AAAAADAAAAAAAAAAAAAAAAAAAAAAAAAAADAAAAA",
                            "AAAAAAAAAAAAAAAAAAAAAAAAAAAAAAAAAAAAAAA", "AAAAAAAAAAAAAAAAAAAAAAAAAAAAAAAAAAAAAAA",
                            "AAAAAAAAAAAAAAAAAAAAAAAAAAAAAAAAAAAAAAA", "AAAAAAAAAAAAAAAAAAAAAAAAAAAAAAAAAAAAAAA",
                            "AAAAAAAAAAAAAAAAAAAAAAAAAAAAAAAAAAAAAAA", "AAAAAAAAAAAAAAAAAAAAAAAAAAAAAAAAAAAAAAA",
                            "AAAAAAAAAAAAAAAAAAAAAAAAAAAAAAAAAAAAAAA", "AAAAAAAAAAAAAAAAAAAAAAAAAAAAAAAAAAAAAAA",
                            "AAAAAAAAAAAAAAAAAAAAAAAAAAAAAAAAAAAAAAA", "AAAAAAAAAAAAAAAAAAAAAAAAAAAAAAAAAAAAAAA",
                            "AAAAAAAAAAAAAAAAAAAAAAAAAAAAAAAAAAAAAAA", "AAAAAAAAAAAAAAAAAAAAAAAAAAAAAAAAAAAAAAA",
                            "AAAAAAAAAAAAAAAAAAAAAAAAAAAAAAAAAAAAAAA", "AAAAAAAAAAAAAAAAAAAAAAAAAAAAAAAAAAAAAAA",
                            "AAAAAAAAAAAAAAAAAAAAAAAAAAAAAAAAAAAAAAA", "AAAAAAAAAAAAAAAAAAAAAAAAAAAAAAAAAAAAAAA",
                            "AAAAAAAAAAAAAAAAAAADAAAAAAAAAAAAAAAAAAA", "AAAAAAAAAAAAAAAAAAAAAAAAAAAAAAAAAAAAAAA")
                    .aisle("AAAAAAAAAAAAAAAAAAAAAAAAAAAAAAAAAAAAAAA", "AAAAAAAAAAAAAAAAAAAAAAAAAAAAAAAAAAAAAAA",
                            "AAAAAAAAAAAAAAAAAAADAAAAAAAAAAAAAAAAAAA", "AAAAAAAAAAAAAAAAAAAAAAAAAAAAAAAAAAAAAAA",
                            "AAAAAAAAAAAAAAAAAAAAAAAAAAAAAAAAAAAAAAA", "AAAAAAAAAAAAAAAAAAAAAAAAAAAAAAAAAAAAAAA",
                            "AAAAAAAAAAAAAAAAAAAAAAAAAAAAAAAAAAAAAAA", "AAAAAAAAAAAAAAAAAAAAAAAAAAAAAAAAAAAAAAA",
                            "AAAAAAAAAAAAAAAAAAAAAAAAAAAAAAAAAAAAAAA", "AAAAAAAAAAAAAAAAAAAAAAAAAAAAAAAAAAAAAAA",
                            "AAAAAAAAAAAAAAAAAAAAAAAAAAAAAAAAAAAAAAA", "AAAAAAAAAAAAAAAAAAAAAAAAAAAAAAAAAAAAAAA",
                            "AAAAAAAAAAAAAAAAAAAAAAAAAAAAAAAAAAAAAAA", "AAAAAAAAAAAAAAAAAAAAAAAAAAAAAAAAAAAAAAA",
                            "AAAAAAAAAAAAAAAAAAAAAAAAAAAAAAAAAAAAAAA", "AAAAAAAAAAAAAAAAAAAAAAAAAAAAAAAAAAAAAAA",
                            "AAAAAAAAAAAAAAAAAAAAAAAAAAAAAAAAAAAAAAA", "AAAAAAAAAAAAAAAAAAAAAAAAAAAAAAAAAAAAAAA",
                            "AAAAAAAAAAAAAAAAAAAAAAAAAAAAAAAAAAAAAAA", "AAAADAAAAAAAAAAAAAAAAAAAAAAAAAAAAADAAAA",
                            "AAABEAAAAAAAAAAAAAAAAAAAAAAAAAAAAAEBAAA", "AAAADAAAAAAAAAAAAAAAAAAAAAAAAAAAAADAAAA",
                            "AAAAAAAAAAAAAAAAAAAAAAAAAAAAAAAAAAAAAAA", "AAAAAAAAAAAAAAAAAAAAAAAAAAAAAAAAAAAAAAA",
                            "AAAAAAAAAAAAAAAAAAAAAAAAAAAAAAAAAAAAAAA", "AAAAAAAAAAAAAAAAAAAAAAAAAAAAAAAAAAAAAAA",
                            "AAAAAAAAAAAAAAAAAAAAAAAAAAAAAAAAAAAAAAA", "AAAAAAAAAAAAAAAAAAAAAAAAAAAAAAAAAAAAAAA",
                            "AAAAAAAAAAAAAAAAAAAAAAAAAAAAAAAAAAAAAAA", "AAAAAAAAAAAAAAAAAAAAAAAAAAAAAAAAAAAAAAA",
                            "AAAAAAAAAAAAAAAAAAAAAAAAAAAAAAAAAAAAAAA", "AAAAAAAAAAAAAAAAAAAAAAAAAAAAAAAAAAAAAAA",
                            "AAAAAAAAAAAAAAAAAAAAAAAAAAAAAAAAAAAAAAA", "AAAAAAAAAAAAAAAAAAAAAAAAAAAAAAAAAAAAAAA",
                            "AAAAAAAAAAAAAAAAAAAAAAAAAAAAAAAAAAAAAAA", "AAAAAAAAAAAAAAAAAAAAAAAAAAAAAAAAAAAAAAA",
                            "AAAAAAAAAAAAAAAAAAAAAAAAAAAAAAAAAAAAAAA", "AAAAAAAAAAAAAAAAAAAAAAAAAAAAAAAAAAAAAAA",
                            "AAAAAAAAAAAAAAAAAAADAAAAAAAAAAAAAAAAAAA", "AAAAAAAAAAAAAAAAAAAAAAAAAAAAAAAAAAAAAAA")
                    .aisle("AAAAAAAAAAAAAAAAAAAAAAAAAAAAAAAAAAAAAAA", "AAAAAAAAAAAAAAAAAAAAAAAAAAAAAAAAAAAAAAA",
                            "AAAAAAAAAAAAAAAAAAADAAAAAAAAAAAAAAAAAAA", "AAAAAAAAAAAAAAAAAAAAAAAAAAAAAAAAAAAAAAA",
                            "AAAAAAAAAAAAAAAAAAAAAAAAAAAAAAAAAAAAAAA", "AAAAAAAAAAAAAAAAAAAAAAAAAAAAAAAAAAAAAAA",
                            "AAAAAAAAAAAAAAAAAAAAAAAAAAAAAAAAAAAAAAA", "AAAAAAAAAAAAAAAAAAAAAAAAAAAAAAAAAAAAAAA",
                            "AAAAAAAAAAAAAAAAAAAAAAAAAAAAAAAAAAAAAAA", "AAAAAAAAAAAAAAAAAAAAAAAAAAAAAAAAAAAAAAA",
                            "AAAAAAAAAAAAAAAAAAAAAAAAAAAAAAAAAAAAAAA", "AAAAAAAAAAAAAAAAAAAAAAAAAAAAAAAAAAAAAAA",
                            "AAAAAAAAAAAAAAAAAAAAAAAAAAAAAAAAAAAAAAA", "AAAAAAAAAAAAAAAAAAAAAAAAAAAAAAAAAAAAAAA",
                            "AAAAAAAAAAAAAAAAAAAAAAAAAAAAAAAAAAAAAAA", "AAAAAAAAAAAAAAAAAAAAAAAAAAAAAAAAAAAAAAA",
                            "AAAAAAAAAAAAAAAAAAAAAAAAAAAAAAAAAAAAAAA", "AAAAAAAAAAAAAAAAAAAAAAAAAAAAAAAAAAAAAAA",
                            "AAAAAAAAAAAAAAAAAAAAAAAAAAAAAAAAAAAAAAA", "AAAADAAAAAAAAAAAAAAAAAAAAAAAAAAAAADAAAA",
                            "AAABEAAAAAAAAAAAAAAAAAAAAAAAAAAAAAEBAAA", "AAAADAAAAAAAAAAAAAAAAAAAAAAAAAAAAADAAAA",
                            "AAAAAAAAAAAAAAAAAAAAAAAAAAAAAAAAAAAAAAA", "AAAAAAAAAAAAAAAAAAAAAAAAAAAAAAAAAAAAAAA",
                            "AAAAAAAAAAAAAAAAAAAAAAAAAAAAAAAAAAAAAAA", "AAAAAAAAAAAAAAAAAAAAAAAAAAAAAAAAAAAAAAA",
                            "AAAAAAAAAAAAAAAAAAAAAAAAAAAAAAAAAAAAAAA", "AAAAAAAAAAAAAAAAAAAAAAAAAAAAAAAAAAAAAAA",
                            "AAAAAAAAAAAAAAAAAAAAAAAAAAAAAAAAAAAAAAA", "AAAAAAAAAAAAAAAAAAAAAAAAAAAAAAAAAAAAAAA",
                            "AAAAAAAAAAAAAAAAAAAAAAAAAAAAAAAAAAAAAAA", "AAAAAAAAAAAAAAAAAAAAAAAAAAAAAAAAAAAAAAA",
                            "AAAAAAAAAAAAAAAAAAAAAAAAAAAAAAAAAAAAAAA", "AAAAAAAAAAAAAAAAAAAAAAAAAAAAAAAAAAAAAAA",
                            "AAAAAAAAAAAAAAAAAAAAAAAAAAAAAAAAAAAAAAA", "AAAAAAAAAAAAAAAAAAAAAAAAAAAAAAAAAAAAAAA",
                            "AAAAAAAAAAAAAAAAAAAAAAAAAAAAAAAAAAAAAAA", "AAAAAAAAAAAAAAAAAAAAAAAAAAAAAAAAAAAAAAA",
                            "AAAAAAAAAAAAAAAAAAADAAAAAAAAAAAAAAAAAAA", "AAAAAAAAAAAAAAAAAAAAAAAAAAAAAAAAAAAAAAA")
                    .aisle("AAAAAAAAAAAAAAAAAAAAAAAAAAAAAAAAAAAAAAA", "AAAAAAAAAAAAAAAAAAAAAAAAAAAAAAAAAAAAAAA",
                            "AAAAAAAAAAAAAAAAAAEDEAAAAAAAAAAAAAAAAAA", "AAAAAAAAAAAAAAAAAAAAAAAAAAAAAAAAAAAAAAA",
                            "AAAAAAAAAAAAAAAAAAAAAAAAAAAAAAAAAAAAAAA", "AAAAAAAAAAAAAAAAAAAAAAAAAAAAAAAAAAAAAAA",
                            "AAAAAAAAAAAAAAAAAAAAAAAAAAAAAAAAAAAAAAA", "AAAAAAAAAAAAAAAAAAAAAAAAAAAAAAAAAAAAAAA",
                            "AAAAAAAAAAAAAAAAAAAAAAAAAAAAAAAAAAAAAAA", "AAAAAAAAAAAAAAAAAAAAAAAAAAAAAAAAAAAAAAA",
                            "AAAAAAAAAAAAAAAAAAAAAAAAAAAAAAAAAAAAAAA", "AAAAAAAAAAAAAAAAAAAAAAAAAAAAAAAAAAAAAAA",
                            "AAAAAAAAAAAAAAAAAAAAAAAAAAAAAAAAAAAAAAA", "AAAAAAAAAAAAAAAAAAAAAAAAAAAAAAAAAAAAAAA",
                            "AAAAAAAAAAAAAAAAAAAAAAAAAAAAAAAAAAAAAAA", "AAAAAAAAAAAAAAAAAAAAAAAAAAAAAAAAAAAAAAA",
                            "AAAAAAAAAAAAAAAAAAAAAAAAAAAAAAAAAAAAAAA", "AAAAAAAAAAAAAAAAAAAAAAAAAAAAAAAAAAAAAAA",
                            "AAAAAAAAAAAAAAAAAAAAAAAAAAAAAAAAAAAAAAA", "AAADAAAAAAAAAAAAAAAAAAAAAAAAAAAAAAADAAA",
                            "AABEAAAAAAAAAAAAAAAAAAAAAAAAAAAAAAAEBAA", "AAADAAAAAAAAAAAAAAAAAAAAAAAAAAAAAAADAAA",
                            "AAAAAAAAAAAAAAAAAAAAAAAAAAAAAAAAAAAAAAA", "AAAAAAAAAAAAAAAAAAAAAAAAAAAAAAAAAAAAAAA",
                            "AAAAAAAAAAAAAAAAAAAAAAAAAAAAAAAAAAAAAAA", "AAAAAAAAAAAAAAAAAAAAAAAAAAAAAAAAAAAAAAA",
                            "AAAAAAAAAAAAAAAAAAAAAAAAAAAAAAAAAAAAAAA", "AAAAAAAAAAAAAAAAAAAAAAAAAAAAAAAAAAAAAAA",
                            "AAAAAAAAAAAAAAAAAAAAAAAAAAAAAAAAAAAAAAA", "AAAAAAAAAAAAAAAAAAAAAAAAAAAAAAAAAAAAAAA",
                            "AAAAAAAAAAAAAAAAAAAAAAAAAAAAAAAAAAAAAAA", "AAAAAAAAAAAAAAAAAAAAAAAAAAAAAAAAAAAAAAA",
                            "AAAAAAAAAAAAAAAAAAAAAAAAAAAAAAAAAAAAAAA", "AAAAAAAAAAAAAAAAAAAAAAAAAAAAAAAAAAAAAAA",
                            "AAAAAAAAAAAAAAAAAAAAAAAAAAAAAAAAAAAAAAA", "AAAAAAAAAAAAAAAAAAAAAAAAAAAAAAAAAAAAAAA",
                            "AAAAAAAAAAAAAAAAAAAAAAAAAAAAAAAAAAAAAAA", "AAAAAAAAAAAAAAAAAAAAAAAAAAAAAAAAAAAAAAA",
                            "AAAAAAAAAAAAAAAAAAEDEAAAAAAAAAAAAAAAAAA", "AAAAAAAAAAAAAAAAAAAAAAAAAAAAAAAAAAAAAAA")
                    .aisle("AAAAAAAAAAAAAAAAAAAAAAAAAAAAAAAAAAAAAAA", "AAAAAAAAAAAAAAAAAAAAAAAAAAAAAAAAAAAAAAA",
                            "AAAAAAAAAAAAAAAAAAEDEAAAAAAAAAAAAAAAAAA", "AAAAAAAAAAAAAAAAAAAAAAAAAAAAAAAAAAAAAAA",
                            "AAAAAAAAAAAAAAAAAAAAAAAAAAAAAAAAAAAAAAA", "AAAAAAAAAAAAAAAAAAAAAAAAAAAAAAAAAAAAAAA",
                            "AAAAAAAAAAAAAAAAAAAAAAAAAAAAAAAAAAAAAAA", "AAAAAAAAAAAAAAAAAAAAAAAAAAAAAAAAAAAAAAA",
                            "AAAAAAAAAAAAAAAAAAAAAAAAAAAAAAAAAAAAAAA", "AAAAAAAAAAAAAAAAAAAAAAAAAAAAAAAAAAAAAAA",
                            "AAAAAAAAAAAAAAAAAAAAAAAAAAAAAAAAAAAAAAA", "AAAAAAAAAAAAAAAAAAAAAAAAAAAAAAAAAAAAAAA",
                            "AAAAAAAAAAAAAAAAAAAAAAAAAAAAAAAAAAAAAAA", "AAAAAAAAAAAAAAAAAAAAAAAAAAAAAAAAAAAAAAA",
                            "AAAAAAAAAAAAAAAAAAAAAAAAAAAAAAAAAAAAAAA", "AAAAAAAAAAAAAAAAAAAAAAAAAAAAAAAAAAAAAAA",
                            "AAAAAAAAAAAAAAAAAAAAAAAAAAAAAAAAAAAAAAA", "AAAAAAAAAAAAAAAAAAAAAAAAAAAAAAAAAAAAAAA",
                            "AAAAAAAAAAAAAAAAAAAAAAAAAAAAAAAAAAAAAAA", "AAADAAAAAAAAAAAAAAAAAAAAAAAAAAAAAAADAAA",
                            "AABEAAAAAAAAAAAAAAAAAAAAAAAAAAAAAAAEBAA", "AAADAAAAAAAAAAAAAAAAAAAAAAAAAAAAAAADAAA",
                            "AAAAAAAAAAAAAAAAAAAAAAAAAAAAAAAAAAAAAAA", "AAAAAAAAAAAAAAAAAAAAAAAAAAAAAAAAAAAAAAA",
                            "AAAAAAAAAAAAAAAAAAAAAAAAAAAAAAAAAAAAAAA", "AAAAAAAAAAAAAAAAAAAAAAAAAAAAAAAAAAAAAAA",
                            "AAAAAAAAAAAAAAAAAAAAAAAAAAAAAAAAAAAAAAA", "AAAAAAAAAAAAAAAAAAAAAAAAAAAAAAAAAAAAAAA",
                            "AAAAAAAAAAAAAAAAAAAAAAAAAAAAAAAAAAAAAAA", "AAAAAAAAAAAAAAAAAAAAAAAAAAAAAAAAAAAAAAA",
                            "AAAAAAAAAAAAAAAAAAAAAAAAAAAAAAAAAAAAAAA", "AAAAAAAAAAAAAAAAAAAAAAAAAAAAAAAAAAAAAAA",
                            "AAAAAAAAAAAAAAAAAAAAAAAAAAAAAAAAAAAAAAA", "AAAAAAAAAAAAAAAAAAAAAAAAAAAAAAAAAAAAAAA",
                            "AAAAAAAAAAAAAAAAAAAAAAAAAAAAAAAAAAAAAAA", "AAAAAAAAAAAAAAAAAAAAAAAAAAAAAAAAAAAAAAA",
                            "AAAAAAAAAAAAAAAAAAAAAAAAAAAAAAAAAAAAAAA", "AAAAAAAAAAAAAAAAAAAAAAAAAAAAAAAAAAAAAAA",
                            "AAAAAAAAAAAAAAAAAAEDEAAAAAAAAAAAAAAAAAA", "AAAAAAAAAAAAAAAAAAAAAAAAAAAAAAAAAAAAAAA")
                    .aisle("AAAAAAAAAAAAAAAAAAAAAAAAAAAAAAAAAAAAAAA", "AAAAAAAAAAAAAAAAAAAAAAAAAAAAAAAAAAAAAAA",
                            "AAAAAAAAAAAAAAAAAAEDEAAAAAAAAAAAAAAAAAA", "AAAAAAAAAAAAAAAAAAAAAAAAAAAAAAAAAAAAAAA",
                            "AAAAAAAAAAAAAAAAAAAAAAAAAAAAAAAAAAAAAAA", "AAAAAAAAAAAAAAAAAAAAAAAAAAAAAAAAAAAAAAA",
                            "AAAAAAAAAAAAAAAAAAAAAAAAAAAAAAAAAAAAAAA", "AAAAAAAAAAAAAAAAAAAAAAAAAAAAAAAAAAAAAAA",
                            "AAAAAAAAAAAAAAAAAAAAAAAAAAAAAAAAAAAAAAA", "AAAAAAAAAAAAAAAAAAAAAAAAAAAAAAAAAAAAAAA",
                            "AAAAAAAAAAAAAAAAAAAAAAAAAAAAAAAAAAAAAAA", "AAAAAAAAAAAAAAAAAAAAAAAAAAAAAAAAAAAAAAA",
                            "AAAAAAAAAAAAAAAAAAAAAAAAAAAAAAAAAAAAAAA", "AAAAAAAAAAAAAAAAAAAAAAAAAAAAAAAAAAAAAAA",
                            "AAAAAAAAAAAAAAAAAAAAAAAAAAAAAAAAAAAAAAA", "AAAAAAAAAAAAAAAAAAAAAAAAAAAAAAAAAAAAAAA",
                            "AAAAAAAAAAAAAAAAAAAAAAAAAAAAAAAAAAAAAAA", "AAAAAAAAAAAAAAAAAAAAAAAAAAAAAAAAAAAAAAA",
                            "AAAAAAAAAAAAAAAAAAAAAAAAAAAAAAAAAAAAAAA", "AAADAAAAAAAAAAAAAAAAAAAAAAAAAAAAAAADAAA",
                            "AABEAAAAAAAAAAAAAAAAAAAAAAAAAAAAAAAEBAA", "AAADAAAAAAAAAAAAAAAAAAAAAAAAAAAAAAADAAA",
                            "AAAAAAAAAAAAAAAAAAAAAAAAAAAAAAAAAAAAAAA", "AAAAAAAAAAAAAAAAAAAAAAAAAAAAAAAAAAAAAAA",
                            "AAAAAAAAAAAAAAAAAAAAAAAAAAAAAAAAAAAAAAA", "AAAAAAAAAAAAAAAAAAAAAAAAAAAAAAAAAAAAAAA",
                            "AAAAAAAAAAAAAAAAAAAAAAAAAAAAAAAAAAAAAAA", "AAAAAAAAAAAAAAAAAAAAAAAAAAAAAAAAAAAAAAA",
                            "AAAAAAAAAAAAAAAAAAAAAAAAAAAAAAAAAAAAAAA", "AAAAAAAAAAAAAAAAAAAAAAAAAAAAAAAAAAAAAAA",
                            "AAAAAAAAAAAAAAAAAAAAAAAAAAAAAAAAAAAAAAA", "AAAAAAAAAAAAAAAAAAAAAAAAAAAAAAAAAAAAAAA",
                            "AAAAAAAAAAAAAAAAAAAAAAAAAAAAAAAAAAAAAAA", "AAAAAAAAAAAAAAAAAAAAAAAAAAAAAAAAAAAAAAA",
                            "AAAAAAAAAAAAAAAAAAAAAAAAAAAAAAAAAAAAAAA", "AAAAAAAAAAAAAAAAAAAAAAAAAAAAAAAAAAAAAAA",
                            "AAAAAAAAAAAAAAAAAAAAAAAAAAAAAAAAAAAAAAA", "AAAAAAAAAAAAAAAAAAAAAAAAAAAAAAAAAAAAAAA",
                            "AAAAAAAAAAAAAAAAAAEDEAAAAAAAAAAAAAAAAAA", "AAAAAAAAAAAAAAAAAAAAAAAAAAAAAAAAAAAAAAA")
                    .aisle("AAAAAAAAAAAAAAAAAAAAAAAAAAAAAAAAAAAAAAA", "AAAAAAAAAAAAAAAAAAAAAAAAAAAAAAAAAAAAAAA",
                            "AAAAAAAAAAAAAAAAAEEDEEAAAAAAAAAAAAAAAAA", "AAAAAAAAAAAAAAAAAAAAAAAAAAAAAAAAAAAAAAA",
                            "AAAAAAAAAAAAAAAAAAAAAAAAAAAAAAAAAAAAAAA", "AAAAAAAAAAAAAAAAAAAAAAAAAAAAAAAAAAAAAAA",
                            "AAAAAAAAAAAAAAAAAAAAAAAAAAAAAAAAAAAAAAA", "AAAAAAAAAAAAAAAAAAAAAAAAAAAAAAAAAAAAAAA",
                            "AAAAAAAAAAAAAAAAAAAAAAAAAAAAAAAAAAAAAAA", "AAAAAAAAAAAAAAAAAAAAAAAAAAAAAAAAAAAAAAA",
                            "AAAAAAAAAAAAAAAAAAAAAAAAAAAAAAAAAAAAAAA", "AAAAAAAAAAAAAAAAAAAAAAAAAAAAAAAAAAAAAAA",
                            "AAAAAAAAAAAAAAAAAAAAAAAAAAAAAAAAAAAAAAA", "AAAAAAAAAAAAAAAAAAAAAAAAAAAAAAAAAAAAAAA",
                            "AAAAAAAAAAAAAAAAAAAAAAAAAAAAAAAAAAAAAAA", "AAAAAAAAAAAAAAAAAAAAAAAAAAAAAAAAAAAAAAA",
                            "AAAAAAAAAAAAAAAAAAAAAAAAAAAAAAAAAAAAAAA", "AAAAAAAAAAAAAAAAAAAAAAAAAAAAAAAAAAAAAAA",
                            "AAAAAAAAAAAAAAAAAAAAAAAAAAAAAAAAAAAAAAA", "AADAAAAAAAAAAAAAAAAAAAAAAAAAAAAAAAAADAA",
                            "ABEAAAAAAAAAAAAAAAAAAAAAAAAAAAAAAAAAEBA", "AADAAAAAAAAAAAAAAAAAAAAAAAAAAAAAAAAADDA",
                            "AAAAAAAAAAAAAAAAAAAAAAAAAAAAAAAAAAAAAAA", "AAAAAAAAAAAAAAAAAAAAAAAAAAAAAAAAAAAAAAA",
                            "AAAAAAAAAAAAAAAAAAAAAAAAAAAAAAAAAAAAAAA", "AAAAAAAAAAAAAAAAAAAAAAAAAAAAAAAAAAAAAAA",
                            "AAAAAAAAAAAAAAAAAAAAAAAAAAAAAAAAAAAAAAA", "AAAAAAAAAAAAAAAAAAAAAAAAAAAAAAAAAAAAAAA",
                            "AAAAAAAAAAAAAAAAAAAAAAAAAAAAAAAAAAAAAAA", "AAAAAAAAAAAAAAAAAAAAAAAAAAAAAAAAAAAAAAA",
                            "AAAAAAAAAAAAAAAAAAAAAAAAAAAAAAAAAAAAAAA", "AAAAAAAAAAAAAAAAAAAAAAAAAAAAAAAAAAAAAAA",
                            "AAAAAAAAAAAAAAAAAAAAAAAAAAAAAAAAAAAAAAA", "AAAAAAAAAAAAAAAAAAAAAAAAAAAAAAAAAAAAAAA",
                            "AAAAAAAAAAAAAAAAAAAAAAAAAAAAAAAAAAAAAAA", "AAAAAAAAAAAAAAAAAAAAAAAAAAAAAAAAAAAAAAA",
                            "AAAAAAAAAAAAAAAAAAAAAAAAAAAAAAAAAAAAAAA", "AAAAAAAAAAAAAAAAAAAAAAAAAAAAAAAAAAAAAAA",
                            "AAAAAAAAAAAAAAAAAEEDEEAAAAAAAAAAAAAAAAA", "AAAAAAAAAAAAAAAAAAAAAAAAAAAAAAAAAAAAAAA")
                    .aisle("AAAAAAAAAAAAAAAAAAAAAAAAAAAAAAAAAAAAAAA", "AAAAAAAAAAAAAAAAAAAAAAAAAAAAAAAAAAAAAAA",
                            "AAAAAAAAAAAAAAAEEEDDDEEEAAAAAAAAAAAAAAA", "AAAAAAAAAAAAAAAAAAAAAAAAAAAAAAAAAAAAAAA",
                            "AAAAAAAAAAAAAAAAAAAAAAAAAAAAAAAAAAAAAAA", "AAAAAAAAAAAAAAAAAAAAAAAAAAAAAAAAAAAAAAA",
                            "AAAAAAAAAAAAAAAAAAAAAAAAAAAAAAAAAAAAAAA", "AAAAAAAAAAAAAAAAAAAAAAAAAAAAAAAAAAAAAAA",
                            "AAAAAAAAAAAAAAAAAAAAAAAAAAAAAAAAAAAAAAA", "AAAAAAAAAAAAAAAAAAAAAAAAAAAAAAAAAAAAAAA",
                            "AAAAAAAAAAAAAAAAAAAAAAAAAAAAAAAAAAAAAAA", "AAAAAAAAAAAAAAAAAAAAAAAAAAAAAAAAAAAAAAA",
                            "AAAAAAAAAAAAAAAAAAAAAAAAAAAAAAAAAAAAAAA", "AAAAAAAAAAAAAAAAAAAAAAAAAAAAAAAAAAAAAAA",
                            "AAAAAAAAAAAAAAAAAAAAAAAAAAAAAAAAAAAAAAA", "AAAAAAAAAAAAAAAAAAAAAAAAAAAAAAAAAAAAAAA",
                            "AAAAAAAAAAAAAAAAAAAAAAAAAAAAAAAAAAAAAAA", "AAAAAAAAAAAAAAAAAAAAAAAAAAAAAAAAAAAAAAA",
                            "AAAAAAAAAAAAAAAAAAAAAAAAAAAAAAAAAAAAAAA", "AADAAAAAAAAAAAAAAAAAAAAAAAAAAAAAAAAADAA",
                            "ABEAAAAAAAAAAAAAAAAAAAAAAAAAAAAAAAAAEBA", "AADAAAAAAAAAAAAAAAAAAAAAAAAAAAAAAAAADDA",
                            "AAAAAAAAAAAAAAAAAAAAAAAAAAAAAAAAAAAAAAA", "AAAAAAAAAAAAAAAAAAAAAAAAAAAAAAAAAAAAAAA",
                            "AAAAAAAAAAAAAAAAAAAAAAAAAAAAAAAAAAAAAAA", "AAAAAAAAAAAAAAAAAAAAAAAAAAAAAAAAAAAAAAA",
                            "AAAAAAAAAAAAAAAAAAAAAAAAAAAAAAAAAAAAAAA", "AAAAAAAAAAAAAAAAAAAAAAAAAAAAAAAAAAAAAAA",
                            "AAAAAAAAAAAAAAAAAAAAAAAAAAAAAAAAAAAAAAA", "AAAAAAAAAAAAAAAAAAAAAAAAAAAAAAAAAAAAAAA",
                            "AAAAAAAAAAAAAAAAAAAAAAAAAAAAAAAAAAAAAAA", "AAAAAAAAAAAAAAAAAAAAAAAAAAAAAAAAAAAAAAA",
                            "AAAAAAAAAAAAAAAAAAAAAAAAAAAAAAAAAAAAAAA", "AAAAAAAAAAAAAAAAAAAAAAAAAAAAAAAAAAAAAAA",
                            "AAAAAAAAAAAAAAAAAAAAAAAAAAAAAAAAAAAAAAA", "AAAAAAAAAAAAAAAAAAAAAAAAAAAAAAAAAAAAAAA",
                            "AAAAAAAAAAAAAAAAAAAAAAAAAAAAAAAAAAAAAAA", "AAAAAAAAAAAAAAAAAAAAAAAAAAAAAAAAAAAAAAA",
                            "AAAAAAAAAAAAAAAEEEDDDEEEAAAAAAAAAAAAAAA", "AAAAAAAAAAAAAAAAAAAAAAAAAAAAAAAAAAAAAAA")
                    .aisle("AAAAAAAAAAAAAAAAAAAAAAAAAAAAAAAAAAAAAAA", "AAAAAAAAAAAAAAAAAAABAAAAAAAAAAAAAAAAAAA",
                            "AAAAAAAAAAAAAAAEDDDEDDDEAAAAAAAAAAAAAAA", "AAAAAAAAAAAAAAAAAAABAAAAAAAAAAAAAAAAAAA",
                            "AAAAAAAAAAAAAAAAAAAAAAAAAAAAAAAAAAAAAAA", "AAAAAAAAAAAAAAAAAAAAAAAAAAAAAAAAAAAAAAA",
                            "AAAAAAAAAAAAAAAAAAAAAAAAAAAAAAAAAAAAAAA", "AAAAAAAAAAAAAAAAAAAAAAAAAAAAAAAAAAAAAAA",
                            "AAAAAAAAAAAAAAAAAAAAAAAAAAAAAAAAAAAAAAA", "AAAAAAAAAAAAAAAAAAAAAAAAAAAAAAAAAAAAAAA",
                            "AAAAAAAAAAAAAAAAAAAAAAAAAAAAAAAAAAAAAAA", "AAAAAAAAAAAAAAAAAAAAAAAAAAAAAAAAAAAAAAA",
                            "AAAAAAAAAAAAAAAAAAAAAAAAAAAAAAAAAAAAAAA", "AAAAAAAAAAAAAAAAAAAAAAAAAAAAAAAAAAAAAAA",
                            "AAAAAAAAAAAAAAAAAAAAAAAAAAAAAAAAAAAAAAA", "AAAAAAAAAAAAAAAAAAAAAAAAAAAAAAAAAAAAAAA",
                            "AAAAAAAAAAAAAAAAAAAAAAAAAAAAAAAAAAAAAAA", "AAAAAAAAAAAAAAAAAAAAAAAAAAAAAAAAAAAAAAA",
                            "AAAAAAAAAAAAAAAAAAAAAAAAAAAAAAAAAAAAAAA", "AADAAAAAAAAAAAAAAAAAAAAAAAAAAAAAAAAADAA",
                            "ABEAAAAAAAAAAAAAAAAAAAAAAAAAAAAAAAAAEBA", "AADAAAAAAAAAAAAAAAAAAAAAAAAAAAAAAAAADDA",
                            "AAAAAAAAAAAAAAAAAAAAAAAAAAAAAAAAAAAAAAA", "AAAAAAAAAAAAAAAAAAAAAAAAAAAAAAAAAAAAAAA",
                            "AAAAAAAAAAAAAAAAAAAAAAAAAAAAAAAAAAAAAAA", "AAAAAAAAAAAAAAAAAAAAAAAAAAAAAAAAAAAAAAA",
                            "AAAAAAAAAAAAAAAAAAAAAAAAAAAAAAAAAAAAAAA", "AAAAAAAAAAAAAAAAAAAAAAAAAAAAAAAAAAAAAAA",
                            "AAAAAAAAAAAAAAAAAAAAAAAAAAAAAAAAAAAAAAA", "AAAAAAAAAAAAAAAAAAAAAAAAAAAAAAAAAAAAAAA",
                            "AAAAAAAAAAAAAAAAAAAAAAAAAAAAAAAAAAAAAAA", "AAAAAAAAAAAAAAAAAAAAAAAAAAAAAAAAAAAAAAA",
                            "AAAAAAAAAAAAAAAAAAAAAAAAAAAAAAAAAAAAAAA", "AAAAAAAAAAAAAAAAAAAAAAAAAAAAAAAAAAAAAAA",
                            "AAAAAAAAAAAAAAAAAAAAAAAAAAAAAAAAAAAAAAA", "AAAAAAAAAAAAAAAAAAAAAAAAAAAAAAAAAAAAAAA",
                            "AAAAAAAAAAAAAAAAAAAAAAAAAAAAAAAAAAAAAAA", "AAAAAAAAAAAAAAAAAAABAAAAAAAAAAAAAAAAAAA",
                            "AAAAAAAAAAAAAAAEDDDEDDDEAAAAAAAAAAAAAAA", "AAAAAAAAAAAAAAAAAAABAAAAAAAAAAAAAAAAAAA")
                    .aisle("AAAAAAAAAAAAAAAAAGAAAGAAAAAAAAAAAAAAAAA", "AAAAAAAAAAAAAAAAAGABAGAAAAAAAAAAAAAAAAA",
                            "AAAAAAAAAAAAAAEEDDDEDDDEEAAAAAAAAAAAAAA", "AAAAAAAAAAAAAAAAAFABAFAAAAAAAAAAAAAAAAA",
                            "AAAAAAAAAAAAAAAAAAAAAAAAAAAAAAAAAAAAAAA", "AAAAAAAAAAAAAAAAAAAAAAAAAAAAAAAAAAAAAAA",
                            "AAAAAAAAAAAAAAAAAAAAAAAAAAAAAAAAAAAAAAA", "AAAAAAAAAAAAAAAAAAAAAAAAAAAAAAAAAAAAAAA",
                            "AAAAAAAAAAAAAAAAAAAAAAAAAAAAAAAAAAAAAAA", "AAAAAAAAAAAAAAAAAAAAAAAAAAAAAAAAAAAAAAA",
                            "AAAAAAAAAAAAAAAAAAAAAAAAAAAAAAAAAAAAAAA", "AAAAAAAAAAAAAAAAAAAAAAAAAAAAAAAAAAAAAAA",
                            "AAAAAAAAAAAAAAAAAAAAAAAAAAAAAAAAAAAAAAA", "AAAAAAAAAAAAAAAAAAAAAAAAAAAAAAAAAAAAAAA",
                            "AAAAAAAAAAAAAAAAAAAAAAAAAAAAAAAAAAAAAAA", "AAAAAAAAAAAAAAAAAAAAAAAAAAAAAAAAAAAAAAA",
                            "AAAAAAAAAAAAAAAAAAAAAAAAAAAAAAAAAAAAAAA", "AAAAAAAAAAAAAAAAAAAAAAAAAAAAAAAAAAAAAAA",
                            "AAAAAAAAAAAAAAAAAAAAAAAAAAAAAAAAAAAAAAA", "ADDAAAAAAAAAAAAAAAAAAAAAAAAAAAAAAAAADDA",
                            "ADDAAAAAAAAAAAAAAAAAAAAAAAAAAAAAAAAADDA", "ADDAAAAAAAAAAAAAAAAAAAAAAAAAAAAAAAAADDA",
                            "AAAAAAAAAAAAAAAAAAAAAAAAAAAAAAAAAAAAAAA", "AAAAAAAAAAAAAAAAAAAAAAAAAAAAAAAAAAAAAAA",
                            "AAAAAAAAAAAAAAAAAAAAAAAAAAAAAAAAAAAAAAA", "AAAAAAAAAAAAAAAAAAAAAAAAAAAAAAAAAAAAAAA",
                            "AAAAAAAAAAAAAAAAAAAAAAAAAAAAAAAAAAAAAAA", "AAAAAAAAAAAAAAAAAAAAAAAAAAAAAAAAAAAAAAA",
                            "AAAAAAAAAAAAAAAAAAAAAAAAAAAAAAAAAAAAAAA", "AAAAAAAAAAAAAAAAAAAAAAAAAAAAAAAAAAAAAAA",
                            "AAAAAAAAAAAAAAAAAAAAAAAAAAAAAAAAAAAAAAA", "AAAAAAAAAAAAAAAAAAAAAAAAAAAAAAAAAAAAAAA",
                            "AAAAAAAAAAAAAAAAAAAAAAAAAAAAAAAAAAAAAAA", "AAAAAAAAAAAAAAAAAAAAAAAAAAAAAAAAAAAAAAA",
                            "AAAAAAAAAAAAAAAAAAAAAAAAAAAAAAAAAAAAAAA", "AAAAAAAAAAAAAAAAAAAAAAAAAAAAAAAAAAAAAAA",
                            "AAAAAAAAAAAAAAAAAAAAAAAAAAAAAAAAAAAAAAA", "AAAAAAAAAAAAAAAAAFABAFAAAAAAAAAAAAAAAAA",
                            "AAAAAAAAAAAAAAEEDDDEDDDEEAAAAAAAAAAAAAA", "AAAAAAAAAAAAAAAAAAABAAAAAAAAAAAAAAAAAAA")
                    .aisle("AAAAAAAAAAAAAAAAAAAAAAAAAAAAAAAAAAAAAAA", "AAAAAAAAAAAAAAAAAAABAAAAAAAAAAAAAAAAAAA",
                            "AAAAAAAAAAAEEEEDDDDEDDDDEEEEAAAAAAAAAAA", "AAAAAAAAAAAAAAAAAAABAAAAAAAAAAAAAAAAAAA",
                            "AAAAAAAAAAAAAAAAAAAAAAAAAAAAAAAAAAAAAAA", "AAAAAAAAAAAAAAAAAAAAAAAAAAAAAAAAAAAAAAA",
                            "AAAAAAAAAAAAAAAAAAAAAAAAAAAAAAAAAAAAAAA", "AAAAAAAAAAAAAAAAAAAAAAAAAAAAAAAAAAAAAAA",
                            "AAAAAAAAAAAAAAAAAAAAAAAAAAAAAAAAAAAAAAA", "AAAAAAAAAAAAAAAAAAAAAAAAAAAAAAAAAAAAAAA",
                            "AAAAAAAAAAAAAAAAAAAAAAAAAAAAAAAAAAAAAAA", "AAAAAAAAAAAAAAAAAAAAAAAAAAAAAAAAAAAAAAA",
                            "AAAAAAAAAAAAAAAAAAAAAAAAAAAAAAAAAAAAAAA", "AAAAAAAAAAAAAAAAAAAAAAAAAAAAAAAAAAAAAAA",
                            "AAAAAAAAAAAAAAAAAAAAAAAAAAAAAAAAAAAAAAA", "AAAAAAAAAAAAAAAAAAAAAAAAAAAAAAAAAAAAAAA",
                            "AAAAAAAAAAAAAAAAAAAAAAAAAAAAAAAAAAAAAAA", "AAAAAAAAAAAAAAAAAAAAAAAAAAAAAAAAAAAAAAA",
                            "ADAAAAAAAAAAAAAAAAAAAAAAAAAAAAAAAAAAADA", "ADDAAAAAAAAAAAAAAAAAAAAAAAAAAAAAAAAADDA",
                            "BEEAAAAAAAAAAAAAAAAAAAAAAAAAAAAAAAAAEEB", "ADDAAAAAAAAAAAAAAAAAAAAAAAAAAAAAAAAADDA",
                            "ADAAAAAAAAAAAAAAAAAAAAAAAAAAAAAAAAAAADA", "AAAAAAAAAAAAAAAAAAAAAAAAAAAAAAAAAAAAAAA",
                            "AAAAAAAAAAAAAAAAAAAAAAAAAAAAAAAAAAAAAAA", "AAAAAAAAAAAAAAAAAAAAAAAAAAAAAAAAAAAAAAA",
                            "AAAAAAAAAAAAAAAAAAAAAAAAAAAAAAAAAAAAAAA", "AAAAAAAAAAAAAAAAAAAAAAAAAAAAAAAAAAAAAAA",
                            "AAAAAAAAAAAAAAAAAAAAAAAAAAAAAAAAAAAAAAA", "AAAAAAAAAAAAAAAAAAAAAAAAAAAAAAAAAAAAAAA",
                            "AAAAAAAAAAAAAAAAAAAAAAAAAAAAAAAAAAAAAAA", "AAAAAAAAAAAAAAAAAAAAAAAAAAAAAAAAAAAAAAA",
                            "AAAAAAAAAAAAAAAAAAAAAAAAAAAAAAAAAAAAAAA", "AAAAAAAAAAAAAAAAAAAAAAAAAAAAAAAAAAAAAAA",
                            "AAAAAAAAAAAAAAAAAAAAAAAAAAAAAAAAAAAAAAA", "AAAAAAAAAAAAAAAAAAAAAAAAAAAAAAAAAAAAAAA",
                            "AAAAAAAAAAAAAAAAAAAAAAAAAAAAAAAAAAAAAAA", "AAAAAAAAAAAAAAAAAAABAAAAAAAAAAAAAAAAAAA",
                            "AAAAAAAAAAAEEEEDDDDEDDDDEEEEAAAAAAAAAAA", "AAAAAAAAAAAAAAAAAAABAAAAAAAAAAAAAAAAAAA")
                    .aisle("AAAAAAAAAAAAAAAAAAAAAAAAAAAAAAAAAAAAAAA", "AAAAAAAAAAAAAAAABBBBBBBAAAAAAAAAAAAAAAA",
                            "AAAAAAAADDDDDDDDEEEEEEEDDDDDDDDAAAAAAAA", "AAAAAAAAAAAAAAAABBBBBBBAAAAAAAAAAAAAAAA",
                            "AAAAAAAAAAAAAAAAAAAAAAAAAAAAAAAAAAAAAAA", "AAAAAAAAAAAAAAAAAAAAAAAAAAAAAAAAAAAAAAA",
                            "AAAAAAAAAAAAAAAAAAAAAAAAAAAAAAAAAAAAAAA", "AAAAAAAAAAAAAAAAAAAAAAAAAAAAAAAAAAAAAAA",
                            "AAAAAAAAAAAAAAAAAAAAAAAAAAAAAAAAAAAAAAA", "AAAAAAAAAAAAAAAAAAAAAAAAAAAAAAAAAAAAAAA",
                            "AAAAAAAAAAAAAAAAAAAAAAAAAAAAAAAAAAAAAAA", "AAAAAAAAAAAAAAAAAAAAAAAAAAAAAAAAAAAAAAA",
                            "AAAAAAAAAAAAAAAAAAAAAAAAAAAAAAAAAAAAAAA", "AAAAAAAAAAAAAAAAAAAAAAAAAAAAAAAAAAAAAAA",
                            "AAAAAAAAAAAAAAAAAAAAAAAAAAAAAAAAAAAAAAA", "ADAAAAAAAAAAAAAAAAAAAAAAAAAAAAAAAAAAADA",
                            "ADAAAAAAAAAAAAAAAAAAAAAAAAAAAAAAAAAAADA", "ADAAAAAAAAAAAAAAAAAAAAAAAAAAAAAAAAAAADA",
                            "ADAAAAAAAAAAAAAAAAAAAAAAAAAAAAAAAAAAADA", "BEDAAAAAAAAAAAAAAAAAAAAAAAAAAAAAAAAADEB",
                            "BEEAAAAAAAAAAAAAAAAAAAAAAAAAAAAAAAAAEEB", "BEDAAAAAAAAAAAAAAAAAAAAAAAAAAAAAAAAADEB",
                            "ADAAAAAAAAAAAAAAAAAAAAAAAAAAAAAAAAAAADA", "ADAAAAAAAAAAAAAAAAAAAAAAAAAAAAAAAAAAADA",
                            "ADAAAAAAAAAAAAAAAAAAAAAAAAAAAAAAAAAAADA", "ADAAAAAAAAAAAAAAAAAAAAAAAAAAAAAAAAAAADA",
                            "AAAAAAAAAAAAAAAAAAAAAAAAAAAAAAAAAAAAADA", "AAAAAAAAAAAAAAAAAAAAAAAAAAAAAAAAAAAAAAA",
                            "AAAAAAAAAAAAAAAAAAAAAAAAAAAAAAAAAAAAAAA", "AAAAAAAAAAAAAAAAAAAAAAAAAAAAAAAAAAAAAAA",
                            "AAAAAAAAAAAAAAAAAAAAAAAAAAAAAAAAAAAAAAA", "AAAAAAAAAAAAAAAAAAAAAAAAAAAAAAAAAAAAAAA",
                            "AAAAAAAAAAAAAAAAAAAAAAAAAAAAAAAAAAAAAAA", "AAAAAAAAAAAAAAAAAAAAAAAAAAAAAAAAAAAAAAA",
                            "AAAAAAAAAAAAAAAAAAAAAAAAAAAAAAAAAAAAAAA", "AAAAAAAAAAAAAAAAAAAAAAAAAAAAAAAAAAAAAAA",
                            "AAAAAAAAAAAAAAAAAAAAAAAAAAAAAAAAAAAAAAA", "AAAAAAAAAAAAAAAABBBBBBBAAAAAAAAAAAAAAAA",
                            "AAAAAAAADDDDDDDDEEEEEEEDDDDDDDDAAAAAAAA", "AAAAAAAAAAAAAAAABBBBBBBAAAAAAAAAAAAAAAA")
                    .aisle("AAAAAAAAAAAAAAAAAAAAAAAAAAAAAAAAAAAAAAA", "AAAAAAAAAAAAAAAAAAABAAAAAAAAAAAAAAAAAAA",
                            "AAAAAAAAAAAEEEEDDDDEDDDDEEEEAAAAAAAAAAA", "AAAAAAAAAAAAAAAAAAABAAAAAAAAAAAAAAAAAAA",
                            "AAAAAAAAAAAAAAAAAAAAAAAAAAAAAAAAAAAAAAA", "AAAAAAAAAAAAAAAAAAAAAAAAAAAAAAAAAAAAAAA",
                            "AAAAAAAAAAAAAAAAAAAAAAAAAAAAAAAAAAAAAAA", "AAAAAAAAAAAAAAAAAAAAAAAAAAAAAAAAAAAAAAA",
                            "AAAAAAAAAAAAAAAAAAAAAAAAAAAAAAAAAAAAAAA", "AAAAAAAAAAAAAAAAAAAAAAAAAAAAAAAAAAAAAAA",
                            "AAAAAAAAAAAAAAAAAAAAAAAAAAAAAAAAAAAAAAA", "AAAAAAAAAAAAAAAAAAAAAAAAAAAAAAAAAAAAAAA",
                            "AAAAAAAAAAAAAAAAAAAAAAAAAAAAAAAAAAAAAAA", "AAAAAAAAAAAAAAAAAAAAAAAAAAAAAAAAAAAAAAA",
                            "AAAAAAAAAAAAAAAAAAAAAAAAAAAAAAAAAAAAAAA", "AAAAAAAAAAAAAAAAAAAAAAAAAAAAAAAAAAAAAAA",
                            "AAAAAAAAAAAAAAAAAAAAAAAAAAAAAAAAAAAAAAA", "AAAAAAAAAAAAAAAAAAAAAAAAAAAAAAAAAAAAAAA",
                            "ADAAAAAAAAAAAAAAAAAAAAAAAAAAAAAAAAAAADA", "ADDAAAAAAAAAAAAAAAAAAAAAAAAAAAAAAAAADDA",
                            "BEEAAAAAAAAAAAAAAAAAAAAAAAAAAAAAAAAAEEB", "ADDAAAAAAAAAAAAAAAAAAAAAAAAAAAAAAAAADDA",
                            "ADAAAAAAAAAAAAAAAAAAAAAAAAAAAAAAAAAAADA", "AAAAAAAAAAAAAAAAAAAAAAAAAAAAAAAAAAAAAAA",
                            "AAAAAAAAAAAAAAAAAAAAAAAAAAAAAAAAAAAAAAA", "AAAAAAAAAAAAAAAAAAAAAAAAAAAAAAAAAAAAAAA",
                            "AAAAAAAAAAAAAAAAAAAAAAAAAAAAAAAAAAAAAAA", "AAAAAAAAAAAAAAAAAAAAAAAAAAAAAAAAAAAAAAA",
                            "AAAAAAAAAAAAAAAAAAAAAAAAAAAAAAAAAAAAAAA", "AAAAAAAAAAAAAAAAAAAAAAAAAAAAAAAAAAAAAAA",
                            "AAAAAAAAAAAAAAAAAAAAAAAAAAAAAAAAAAAAAAA", "AAAAAAAAAAAAAAAAAAAAAAAAAAAAAAAAAAAAAAA",
                            "AAAAAAAAAAAAAAAAAAAAAAAAAAAAAAAAAAAAAAA", "AAAAAAAAAAAAAAAAAAAAAAAAAAAAAAAAAAAAAAA",
                            "AAAAAAAAAAAAAAAAAAAAAAAAAAAAAAAAAAAAAAA", "AAAAAAAAAAAAAAAAAAAAAAAAAAAAAAAAAAAAAAA",
                            "AAAAAAAAAAAAAAAAAAAAAAAAAAAAAAAAAAAAAAA", "AAAAAAAAAAAAAAAAAAABAAAAAAAAAAAAAAAAAAA",
                            "AAAAAAAAAAAEEEEDDDDEDDDDEEEEAAAAAAAAAAA", "AAAAAAAAAAAAAAAAAAABAAAAAAAAAAAAAAAAAAA")
                    .aisle("AAAAAAAAAAAAAAAAAGAAAGAAAAAAAAAAAAAAAAA", "AAAAAAAAAAAAAAAAAGABAGAAAAAAAAAAAAAAAAA",
                            "AAAAAAAAAAAAAAEEDDDEDDDEEAAAAAAAAAAAAAA", "AAAAAAAAAAAAAAAAAFABAFAAAAAAAAAAAAAAAAA",
                            "AAAAAAAAAAAAAAAAAAAAAAAAAAAAAAAAAAAAAAA", "AAAAAAAAAAAAAAAAAAAAAAAAAAAAAAAAAAAAAAA",
                            "AAAAAAAAAAAAAAAAAAAAAAAAAAAAAAAAAAAAAAA", "AAAAAAAAAAAAAAAAAAAAAAAAAAAAAAAAAAAAAAA",
                            "AAAAAAAAAAAAAAAAAAAAAAAAAAAAAAAAAAAAAAA", "AAAAAAAAAAAAAAAAAAAAAAAAAAAAAAAAAAAAAAA",
                            "AAAAAAAAAAAAAAAAAAAAAAAAAAAAAAAAAAAAAAA", "AAAAAAAAAAAAAAAAAAAAAAAAAAAAAAAAAAAAAAA",
                            "AAAAAAAAAAAAAAAAAAAAAAAAAAAAAAAAAAAAAAA", "AAAAAAAAAAAAAAAAAAAAAAAAAAAAAAAAAAAAAAA",
                            "AAAAAAAAAAAAAAAAAAAAAAAAAAAAAAAAAAAAAAA", "AAAAAAAAAAAAAAAAAAAAAAAAAAAAAAAAAAAAAAA",
                            "AAAAAAAAAAAAAAAAAAAAAAAAAAAAAAAAAAAAAAA", "AAAAAAAAAAAAAAAAAAAAAAAAAAAAAAAAAAAAAAA",
                            "AAAAAAAAAAAAAAAAAAAAAAAAAAAAAAAAAAAAAAA", "ADDAAAAAAAAAAAAAAAAAAAAAAAAAAAAAAAAADDA",
                            "ADDAAAAAAAAAAAAAAAAAAAAAAAAAAAAAAAAADDA", "ADDAAAAAAAAAAAAAAAAAAAAAAAAAAAAAAAAADDA",
                            "AAAAAAAAAAAAAAAAAAAAAAAAAAAAAAAAAAAAAAA", "AAAAAAAAAAAAAAAAAAAAAAAAAAAAAAAAAAAAAAA",
                            "AAAAAAAAAAAAAAAAAAAAAAAAAAAAAAAAAAAAAAA", "AAAAAAAAAAAAAAAAAAAAAAAAAAAAAAAAAAAAAAA",
                            "AAAAAAAAAAAAAAAAAAAAAAAAAAAAAAAAAAAAAAA", "AAAAAAAAAAAAAAAAAAAAAAAAAAAAAAAAAAAAAAA",
                            "AAAAAAAAAAAAAAAAAAAAAAAAAAAAAAAAAAAAAAA", "AAAAAAAAAAAAAAAAAAAAAAAAAAAAAAAAAAAAAAA",
                            "AAAAAAAAAAAAAAAAAAAAAAAAAAAAAAAAAAAAAAA", "AAAAAAAAAAAAAAAAAAAAAAAAAAAAAAAAAAAAAAA",
                            "AAAAAAAAAAAAAAAAAAAAAAAAAAAAAAAAAAAAAAA", "AAAAAAAAAAAAAAAAAAAAAAAAAAAAAAAAAAAAAAA",
                            "AAAAAAAAAAAAAAAAAAAAAAAAAAAAAAAAAAAAAAA", "AAAAAAAAAAAAAAAAAAAAAAAAAAAAAAAAAAAAAAA",
                            "AAAAAAAAAAAAAAAAAAAAAAAAAAAAAAAAAAAAAAA", "AAAAAAAAAAAAAAAAAFABAFAAAAAAAAAAAAAAAAA",
                            "AAAAAAAAAAAAAAEEDDDEDDDEEAAAAAAAAAAAAAA", "AAAAAAAAAAAAAAAAAAABAAAAAAAAAAAAAAAAAAA")
                    .aisle("AAAAAAAAAAAAAAAAAAAAAAAAAAAAAAAAAAAAAAA", "AAAAAAAAAAAAAAAAAAABAAAAAAAAAAAAAAAAAAA",
                            "AAAAAAAAAAAAAAAEDDDEDDDEAAAAAAAAAAAAAAA", "AAAAAAAAAAAAAAAAAAABAAAAAAAAAAAAAAAAAAA",
                            "AAAAAAAAAAAAAAAAAAAAAAAAAAAAAAAAAAAAAAA", "AAAAAAAAAAAAAAAAAAAAAAAAAAAAAAAAAAAAAAA",
                            "AAAAAAAAAAAAAAAAAAAAAAAAAAAAAAAAAAAAAAA", "AAAAAAAAAAAAAAAAAAAAAAAAAAAAAAAAAAAAAAA",
                            "AAAAAAAAAAAAAAAAAAAAAAAAAAAAAAAAAAAAAAA", "AAAAAAAAAAAAAAAAAAAAAAAAAAAAAAAAAAAAAAA",
                            "AAAAAAAAAAAAAAAAAAAAAAAAAAAAAAAAAAAAAAA", "AAAAAAAAAAAAAAAAAAAAAAAAAAAAAAAAAAAAAAA",
                            "AAAAAAAAAAAAAAAAAAAAAAAAAAAAAAAAAAAAAAA", "AAAAAAAAAAAAAAAAAAAAAAAAAAAAAAAAAAAAAAA",
                            "AAAAAAAAAAAAAAAAAAAAAAAAAAAAAAAAAAAAAAA", "AAAAAAAAAAAAAAAAAAAAAAAAAAAAAAAAAAAAAAA",
                            "AAAAAAAAAAAAAAAAAAAAAAAAAAAAAAAAAAAAAAA", "AAAAAAAAAAAAAAAAAAAAAAAAAAAAAAAAAAAAAAA",
                            "AAAAAAAAAAAAAAAAAAAAAAAAAAAAAAAAAAAAAAA", "AADAAAAAAAAAAAAAAAAAAAAAAAAAAAAAAAAADAA",
                            "ABEAAAAAAAAAAAAAAAAAAAAAAAAAAAAAAAAAEBA", "AADAAAAAAAAAAAAAAAAAAAAAAAAAAAAAAAAADAA",
                            "AAAAAAAAAAAAAAAAAAAAAAAAAAAAAAAAAAAAAAA", "AAAAAAAAAAAAAAAAAAAAAAAAAAAAAAAAAAAAAAA",
                            "AAAAAAAAAAAAAAAAAAAAAAAAAAAAAAAAAAAAAAA", "AAAAAAAAAAAAAAAAAAAAAAAAAAAAAAAAAAAAAAA",
                            "AAAAAAAAAAAAAAAAAAAAAAAAAAAAAAAAAAAAAAA", "AAAAAAAAAAAAAAAAAAAAAAAAAAAAAAAAAAAAAAA",
                            "AAAAAAAAAAAAAAAAAAAAAAAAAAAAAAAAAAAAAAA", "AAAAAAAAAAAAAAAAAAAAAAAAAAAAAAAAAAAAAAA",
                            "AAAAAAAAAAAAAAAAAAAAAAAAAAAAAAAAAAAAAAA", "AAAAAAAAAAAAAAAAAAAAAAAAAAAAAAAAAAAAAAA",
                            "AAAAAAAAAAAAAAAAAAAAAAAAAAAAAAAAAAAAAAA", "AAAAAAAAAAAAAAAAAAAAAAAAAAAAAAAAAAAAAAA",
                            "AAAAAAAAAAAAAAAAAAAAAAAAAAAAAAAAAAAAAAA", "AAAAAAAAAAAAAAAAAAAAAAAAAAAAAAAAAAAAAAA",
                            "AAAAAAAAAAAAAAAAAAAAAAAAAAAAAAAAAAAAAAA", "AAAAAAAAAAAAAAAAAAABAAAAAAAAAAAAAAAAAAA",
                            "AAAAAAAAAAAAAAAEDDDEDDDEAAAAAAAAAAAAAAA", "AAAAAAAAAAAAAAAAAAABAAAAAAAAAAAAAAAAAAA")
                    .aisle("AAAAAAAAAAAAAAAAAAAAAAAAAAAAAAAAAAAAAAA", "AAAAAAAAAAAAAAAAAAAAAAAAAAAAAAAAAAAAAAA",
                            "AAAAAAAAAAAAAAAEEEDDDEEEAAAAAAAAAAAAAAA", "AAAAAAAAAAAAAAAAAAAAAAAAAAAAAAAAAAAAAAA",
                            "AAAAAAAAAAAAAAAAAAAAAAAAAAAAAAAAAAAAAAA", "AAAAAAAAAAAAAAAAAAAAAAAAAAAAAAAAAAAAAAA",
                            "AAAAAAAAAAAAAAAAAAAAAAAAAAAAAAAAAAAAAAA", "AAAAAAAAAAAAAAAAAAAAAAAAAAAAAAAAAAAAAAA",
                            "AAAAAAAAAAAAAAAAAAAAAAAAAAAAAAAAAAAAAAA", "AAAAAAAAAAAAAAAAAAAAAAAAAAAAAAAAAAAAAAA",
                            "AAAAAAAAAAAAAAAAAAAAAAAAAAAAAAAAAAAAAAA", "AAAAAAAAAAAAAAAAAAAAAAAAAAAAAAAAAAAAAAA",
                            "AAAAAAAAAAAAAAAAAAAAAAAAAAAAAAAAAAAAAAA", "AAAAAAAAAAAAAAAAAAAAAAAAAAAAAAAAAAAAAAA",
                            "AAAAAAAAAAAAAAAAAAAAAAAAAAAAAAAAAAAAAAA", "AAAAAAAAAAAAAAAAAAAAAAAAAAAAAAAAAAAAAAA",
                            "AAAAAAAAAAAAAAAAAAAAAAAAAAAAAAAAAAAAAAA", "AAAAAAAAAAAAAAAAAAAAAAAAAAAAAAAAAAAAAAA",
                            "AAAAAAAAAAAAAAAAAAAAAAAAAAAAAAAAAAAAAAA", "AADAAAAAAAAAAAAAAAAAAAAAAAAAAAAAAAAADAA",
                            "ABEAAAAAAAAAAAAAAAAAAAAAAAAAAAAAAAAAEBA", "AADAAAAAAAAAAAAAAAAAAAAAAAAAAAAAAAAADAA",
                            "AAAAAAAAAAAAAAAAAAAAAAAAAAAAAAAAAAAAAAA", "AAAAAAAAAAAAAAAAAAAAAAAAAAAAAAAAAAAAAAA",
                            "AAAAAAAAAAAAAAAAAAAAAAAAAAAAAAAAAAAAAAA", "AAAAAAAAAAAAAAAAAAAAAAAAAAAAAAAAAAAAAAA",
                            "AAAAAAAAAAAAAAAAAAAAAAAAAAAAAAAAAAAAAAA", "AAAAAAAAAAAAAAAAAAAAAAAAAAAAAAAAAAAAAAA",
                            "AAAAAAAAAAAAAAAAAAAAAAAAAAAAAAAAAAAAAAA", "AAAAAAAAAAAAAAAAAAAAAAAAAAAAAAAAAAAAAAA",
                            "AAAAAAAAAAAAAAAAAAAAAAAAAAAAAAAAAAAAAAA", "AAAAAAAAAAAAAAAAAAAAAAAAAAAAAAAAAAAAAAA",
                            "AAAAAAAAAAAAAAAAAAAAAAAAAAAAAAAAAAAAAAA", "AAAAAAAAAAAAAAAAAAAAAAAAAAAAAAAAAAAAAAA",
                            "AAAAAAAAAAAAAAAAAAAAAAAAAAAAAAAAAAAAAAA", "AAAAAAAAAAAAAAAAAAAAAAAAAAAAAAAAAAAAAAA",
                            "AAAAAAAAAAAAAAAAAAAAAAAAAAAAAAAAAAAAAAA", "AAAAAAAAAAAAAAAAAAAAAAAAAAAAAAAAAAAAAAA",
                            "AAAAAAAAAAAAAAAEEEDDDEEEAAAAAAAAAAAAAAA", "AAAAAAAAAAAAAAAAAAAAAAAAAAAAAAAAAAAAAAA")
                    .aisle("AAAAAAAAAAAAAAAAAAAAAAAAAAAAAAAAAAAAAAA", "AAAAAAAAAAAAAAAAAAAAAAAAAAAAAAAAAAAAAAA",
                            "AAAAAAAAAAAAAAAAAEEDEEAAAAAAAAAAAAAAAAA", "AAAAAAAAAAAAAAAAAAAAAAAAAAAAAAAAAAAAAAA",
                            "AAAAAAAAAAAAAAAAAAAAAAAAAAAAAAAAAAAAAAA", "AAAAAAAAAAAAAAAAAAAAAAAAAAAAAAAAAAAAAAA",
                            "AAAAAAAAAAAAAAAAAAAAAAAAAAAAAAAAAAAAAAA", "AAAAAAAAAAAAAAAAAAAAAAAAAAAAAAAAAAAAAAA",
                            "AAAAAAAAAAAAAAAAAAAAAAAAAAAAAAAAAAAAAAA", "AAAAAAAAAAAAAAAAAAAAAAAAAAAAAAAAAAAAAAA",
                            "AAAAAAAAAAAAAAAAAAAAAAAAAAAAAAAAAAAAAAA", "AAAAAAAAAAAAAAAAAAAAAAAAAAAAAAAAAAAAAAA",
                            "AAAAAAAAAAAAAAAAAAAAAAAAAAAAAAAAAAAAAAA", "AAAAAAAAAAAAAAAAAAAAAAAAAAAAAAAAAAAAAAA",
                            "AAAAAAAAAAAAAAAAAAAAAAAAAAAAAAAAAAAAAAA", "AAAAAAAAAAAAAAAAAAAAAAAAAAAAAAAAAAAAAAA",
                            "AAAAAAAAAAAAAAAAAAAAAAAAAAAAAAAAAAAAAAA", "AAAAAAAAAAAAAAAAAAAAAAAAAAAAAAAAAAAAAAA",
                            "AAAAAAAAAAAAAAAAAAAAAAAAAAAAAAAAAAAAAAA", "AADAAAAAAAAAAAAAAAAAAAAAAAAAAAAAAAAADAA",
                            "ABEAAAAAAAAAAAAAAAAAAAAAAAAAAAAAAAAAEBA", "AADAAAAAAAAAAAAAAAAAAAAAAAAAAAAAAAAADAA",
                            "AAAAAAAAAAAAAAAAAAAAAAAAAAAAAAAAAAAAAAA", "AAAAAAAAAAAAAAAAAAAAAAAAAAAAAAAAAAAAAAA",
                            "AAAAAAAAAAAAAAAAAAAAAAAAAAAAAAAAAAAAAAA", "AAAAAAAAAAAAAAAAAAAAAAAAAAAAAAAAAAAAAAA",
                            "AAAAAAAAAAAAAAAAAAAAAAAAAAAAAAAAAAAAAAA", "AAAAAAAAAAAAAAAAAAAAAAAAAAAAAAAAAAAAAAA",
                            "AAAAAAAAAAAAAAAAAAAAAAAAAAAAAAAAAAAAAAA", "AAAAAAAAAAAAAAAAAAAAAAAAAAAAAAAAAAAAAAA",
                            "AAAAAAAAAAAAAAAAAAAAAAAAAAAAAAAAAAAAAAA", "AAAAAAAAAAAAAAAAAAAAAAAAAAAAAAAAAAAAAAA",
                            "AAAAAAAAAAAAAAAAAAAAAAAAAAAAAAAAAAAAAAA", "AAAAAAAAAAAAAAAAAAAAAAAAAAAAAAAAAAAAAAA",
                            "AAAAAAAAAAAAAAAAAAAAAAAAAAAAAAAAAAAAAAA", "AAAAAAAAAAAAAAAAAAAAAAAAAAAAAAAAAAAAAAA",
                            "AAAAAAAAAAAAAAAAAAAAAAAAAAAAAAAAAAAAAAA", "AAAAAAAAAAAAAAAAAAAAAAAAAAAAAAAAAAAAAAA",
                            "AAAAAAAAAAAAAAAAAEEDEEAAAAAAAAAAAAAAAAA", "AAAAAAAAAAAAAAAAAAAAAAAAAAAAAAAAAAAAAAA")
                    .aisle("AAAAAAAAAAAAAAAAAAAAAAAAAAAAAAAAAAAAAAA", "AAAAAAAAAAAAAAAAAAAAAAAAAAAAAAAAAAAAAAA",
                            "AAAAAAAAAAAAAAAAAAEDEAAAAAAAAAAAAAAAAAA", "AAAAAAAAAAAAAAAAAAAAAAAAAAAAAAAAAAAAAAA",
                            "AAAAAAAAAAAAAAAAAAAAAAAAAAAAAAAAAAAAAAA", "AAAAAAAAAAAAAAAAAAAAAAAAAAAAAAAAAAAAAAA",
                            "AAAAAAAAAAAAAAAAAAAAAAAAAAAAAAAAAAAAAAA", "AAAAAAAAAAAAAAAAAAAAAAAAAAAAAAAAAAAAAAA",
                            "AAAAAAAAAAAAAAAAAAAAAAAAAAAAAAAAAAAAAAA", "AAAAAAAAAAAAAAAAAAAAAAAAAAAAAAAAAAAAAAA",
                            "AAAAAAAAAAAAAAAAAAAAAAAAAAAAAAAAAAAAAAA", "AAAAAAAAAAAAAAAAAAAAAAAAAAAAAAAAAAAAAAA",
                            "AAAAAAAAAAAAAAAAAAAAAAAAAAAAAAAAAAAAAAA", "AAAAAAAAAAAAAAAAAAAAAAAAAAAAAAAAAAAAAAA",
                            "AAAAAAAAAAAAAAAAAAAAAAAAAAAAAAAAAAAAAAA", "AAAAAAAAAAAAAAAAAAAAAAAAAAAAAAAAAAAAAAA",
                            "AAAAAAAAAAAAAAAAAAAAAAAAAAAAAAAAAAAAAAA", "AAAAAAAAAAAAAAAAAAAAAAAAAAAAAAAAAAAAAAA",
                            "AAAAAAAAAAAAAAAAAAAAAAAAAAAAAAAAAAAAAAA", "AAADAAAAAAAAAAAAAAAAAAAAAAAAAAAAAAADAAA",
                            "AABEAAAAAAAAAAAAAAAAAAAAAAAAAAAAAAAEBAA", "AAADAAAAAAAAAAAAAAAAAAAAAAAAAAAAAAADAAA",
                            "AAAAAAAAAAAAAAAAAAAAAAAAAAAAAAAAAAAAAAA", "AAAAAAAAAAAAAAAAAAAAAAAAAAAAAAAAAAAAAAA",
                            "AAAAAAAAAAAAAAAAAAAAAAAAAAAAAAAAAAAAAAA", "AAAAAAAAAAAAAAAAAAAAAAAAAAAAAAAAAAAAAAA",
                            "AAAAAAAAAAAAAAAAAAAAAAAAAAAAAAAAAAAAAAA", "AAAAAAAAAAAAAAAAAAAAAAAAAAAAAAAAAAAAAAA",
                            "AAAAAAAAAAAAAAAAAAAAAAAAAAAAAAAAAAAAAAA", "AAAAAAAAAAAAAAAAAAAAAAAAAAAAAAAAAAAAAAA",
                            "AAAAAAAAAAAAAAAAAAAAAAAAAAAAAAAAAAAAAAA", "AAAAAAAAAAAAAAAAAAAAAAAAAAAAAAAAAAAAAAA",
                            "AAAAAAAAAAAAAAAAAAAAAAAAAAAAAAAAAAAAAAA", "AAAAAAAAAAAAAAAAAAAAAAAAAAAAAAAAAAAAAAA",
                            "AAAAAAAAAAAAAAAAAAAAAAAAAAAAAAAAAAAAAAA", "AAAAAAAAAAAAAAAAAAAAAAAAAAAAAAAAAAAAAAA",
                            "AAAAAAAAAAAAAAAAAAAAAAAAAAAAAAAAAAAAAAA", "AAAAAAAAAAAAAAAAAAAAAAAAAAAAAAAAAAAAAAA",
                            "AAAAAAAAAAAAAAAAAAEDEAAAAAAAAAAAAAAAAAA", "AAAAAAAAAAAAAAAAAAAAAAAAAAAAAAAAAAAAAAA")
                    .aisle("AAAAAAAAAAAAAAAAAAAAAAAAAAAAAAAAAAAAAAA", "AAAAAAAAAAAAAAAAAAAAAAAAAAAAAAAAAAAAAAA",
                            "AAAAAAAAAAAAAAAAAAEDEAAAAAAAAAAAAAAAAAA", "AAAAAAAAAAAAAAAAAAAAAAAAAAAAAAAAAAAAAAA",
                            "AAAAAAAAAAAAAAAAAAAAAAAAAAAAAAAAAAAAAAA", "AAAAAAAAAAAAAAAAAAAAAAAAAAAAAAAAAAAAAAA",
                            "AAAAAAAAAAAAAAAAAAAAAAAAAAAAAAAAAAAAAAA", "AAAAAAAAAAAAAAAAAAAAAAAAAAAAAAAAAAAAAAA",
                            "AAAAAAAAAAAAAAAAAAAAAAAAAAAAAAAAAAAAAAA", "AAAAAAAAAAAAAAAAAAAAAAAAAAAAAAAAAAAAAAA",
                            "AAAAAAAAAAAAAAAAAAAAAAAAAAAAAAAAAAAAAAA", "AAAAAAAAAAAAAAAAAAAAAAAAAAAAAAAAAAAAAAA",
                            "AAAAAAAAAAAAAAAAAAAAAAAAAAAAAAAAAAAAAAA", "AAAAAAAAAAAAAAAAAAAAAAAAAAAAAAAAAAAAAAA",
                            "AAAAAAAAAAAAAAAAAAAAAAAAAAAAAAAAAAAAAAA", "AAAAAAAAAAAAAAAAAAAAAAAAAAAAAAAAAAAAAAA",
                            "AAAAAAAAAAAAAAAAAAAAAAAAAAAAAAAAAAAAAAA", "AAAAAAAAAAAAAAAAAAAAAAAAAAAAAAAAAAAAAAA",
                            "AAAAAAAAAAAAAAAAAAAAAAAAAAAAAAAAAAAAAAA", "AAADAAAAAAAAAAAAAAAAAAAAAAAAAAAAAAADAAA",
                            "AABEAAAAAAAAAAAAAAAAAAAAAAAAAAAAAAAEBAA", "AAADAAAAAAAAAAAAAAAAAAAAAAAAAAAAAAADAAA",
                            "AAAAAAAAAAAAAAAAAAAAAAAAAAAAAAAAAAAAAAA", "AAAAAAAAAAAAAAAAAAAAAAAAAAAAAAAAAAAAAAA",
                            "AAAAAAAAAAAAAAAAAAAAAAAAAAAAAAAAAAAAAAA", "AAAAAAAAAAAAAAAAAAAAAAAAAAAAAAAAAAAAAAA",
                            "AAAAAAAAAAAAAAAAAAAAAAAAAAAAAAAAAAAAAAA", "AAAAAAAAAAAAAAAAAAAAAAAAAAAAAAAAAAAAAAA",
                            "AAAAAAAAAAAAAAAAAAAAAAAAAAAAAAAAAAAAAAA", "AAAAAAAAAAAAAAAAAAAAAAAAAAAAAAAAAAAAAAA",
                            "AAAAAAAAAAAAAAAAAAAAAAAAAAAAAAAAAAAAAAA", "AAAAAAAAAAAAAAAAAAAAAAAAAAAAAAAAAAAAAAA",
                            "AAAAAAAAAAAAAAAAAAAAAAAAAAAAAAAAAAAAAAA", "AAAAAAAAAAAAAAAAAAAAAAAAAAAAAAAAAAAAAAA",
                            "AAAAAAAAAAAAAAAAAAAAAAAAAAAAAAAAAAAAAAA", "AAAAAAAAAAAAAAAAAAAAAAAAAAAAAAAAAAAAAAA",
                            "AAAAAAAAAAAAAAAAAAAAAAAAAAAAAAAAAAAAAAA", "AAAAAAAAAAAAAAAAAAAAAAAAAAAAAAAAAAAAAAA",
                            "AAAAAAAAAAAAAAAAAAEDEAAAAAAAAAAAAAAAAAA", "AAAAAAAAAAAAAAAAAAAAAAAAAAAAAAAAAAAAAAA")
                    .aisle("AAAAAAAAAAAAAAAAAAAAAAAAAAAAAAAAAAAAAAA", "AAAAAAAAAAAAAAAAAAAAAAAAAAAAAAAAAAAAAAA",
                            "AAAAAAAAAAAAAAAAAAEDEAAAAAAAAAAAAAAAAAA", "AAAAAAAAAAAAAAAAAAAAAAAAAAAAAAAAAAAAAAA",
                            "AAAAAAAAAAAAAAAAAAAAAAAAAAAAAAAAAAAAAAA", "AAAAAAAAAAAAAAAAAAAAAAAAAAAAAAAAAAAAAAA",
                            "AAAAAAAAAAAAAAAAAAAAAAAAAAAAAAAAAAAAAAA", "AAAAAAAAAAAAAAAAAAAAAAAAAAAAAAAAAAAAAAA",
                            "AAAAAAAAAAAAAAAAAAAAAAAAAAAAAAAAAAAAAAA", "AAAAAAAAAAAAAAAAAAAAAAAAAAAAAAAAAAAAAAA",
                            "AAAAAAAAAAAAAAAAAAAAAAAAAAAAAAAAAAAAAAA", "AAAAAAAAAAAAAAAAAAAAAAAAAAAAAAAAAAAAAAA",
                            "AAAAAAAAAAAAAAAAAAAAAAAAAAAAAAAAAAAAAAA", "AAAAAAAAAAAAAAAAAAAAAAAAAAAAAAAAAAAAAAA",
                            "AAAAAAAAAAAAAAAAAAAAAAAAAAAAAAAAAAAAAAA", "AAAAAAAAAAAAAAAAAAAAAAAAAAAAAAAAAAAAAAA",
                            "AAAAAAAAAAAAAAAAAAAAAAAAAAAAAAAAAAAAAAA", "AAAAAAAAAAAAAAAAAAAAAAAAAAAAAAAAAAAAAAA",
                            "AAAAAAAAAAAAAAAAAAAAAAAAAAAAAAAAAAAAAAA", "AAADAAAAAAAAAAAAAAAAAAAAAAAAAAAAAAADAAA",
                            "AABEAAAAAAAAAAAAAAAAAAAAAAAAAAAAAAAEBAA", "AAADAAAAAAAAAAAAAAAAAAAAAAAAAAAAAAADAAA",
                            "AAAAAAAAAAAAAAAAAAAAAAAAAAAAAAAAAAAAAAA", "AAAAAAAAAAAAAAAAAAAAAAAAAAAAAAAAAAAAAAA",
                            "AAAAAAAAAAAAAAAAAAAAAAAAAAAAAAAAAAAAAAA", "AAAAAAAAAAAAAAAAAAAAAAAAAAAAAAAAAAAAAAA",
                            "AAAAAAAAAAAAAAAAAAAAAAAAAAAAAAAAAAAAAAA", "AAAAAAAAAAAAAAAAAAAAAAAAAAAAAAAAAAAAAAA",
                            "AAAAAAAAAAAAAAAAAAAAAAAAAAAAAAAAAAAAAAA", "AAAAAAAAAAAAAAAAAAAAAAAAAAAAAAAAAAAAAAA",
                            "AAAAAAAAAAAAAAAAAAAAAAAAAAAAAAAAAAAAAAA", "AAAAAAAAAAAAAAAAAAAAAAAAAAAAAAAAAAAAAAA",
                            "AAAAAAAAAAAAAAAAAAAAAAAAAAAAAAAAAAAAAAA", "AAAAAAAAAAAAAAAAAAAAAAAAAAAAAAAAAAAAAAA",
                            "AAAAAAAAAAAAAAAAAAAAAAAAAAAAAAAAAAAAAAA", "AAAAAAAAAAAAAAAAAAAAAAAAAAAAAAAAAAAAAAA",
                            "AAAAAAAAAAAAAAAAAAAAAAAAAAAAAAAAAAAAAAA", "AAAAAAAAAAAAAAAAAAAAAAAAAAAAAAAAAAAAAAA",
                            "AAAAAAAAAAAAAAAAAAEDEAAAAAAAAAAAAAAAAAA", "AAAAAAAAAAAAAAAAAAAAAAAAAAAAAAAAAAAAAAA")
                    .aisle("AAAAAAAAAAAAAAAAAAAAAAAAAAAAAAAAAAAAAAA", "AAAAAAAAAAAAAAAAAAAAAAAAAAAAAAAAAAAAAAA",
                            "AAAAAAAAAAAAAAAAAAADAAAAAAAAAAAAAAAAAAA", "AAAAAAAAAAAAAAAAAAAAAAAAAAAAAAAAAAAAAAA",
                            "AAAAAAAAAAAAAAAAAAAAAAAAAAAAAAAAAAAAAAA", "AAAAAAAAAAAAAAAAAAAAAAAAAAAAAAAAAAAAAAA",
                            "AAAAAAAAAAAAAAAAAAAAAAAAAAAAAAAAAAAAAAA", "AAAAAAAAAAAAAAAAAAAAAAAAAAAAAAAAAAAAAAA",
                            "AAAAAAAAAAAAAAAAAAAAAAAAAAAAAAAAAAAAAAA", "AAAAAAAAAAAAAAAAAAAAAAAAAAAAAAAAAAAAAAA",
                            "AAAAAAAAAAAAAAAAAAAAAAAAAAAAAAAAAAAAAAA", "AAAAAAAAAAAAAAAAAAAAAAAAAAAAAAAAAAAAAAA",
                            "AAAAAAAAAAAAAAAAAAAAAAAAAAAAAAAAAAAAAAA", "AAAAAAAAAAAAAAAAAAAAAAAAAAAAAAAAAAAAAAA",
                            "AAAAAAAAAAAAAAAAAAAAAAAAAAAAAAAAAAAAAAA", "AAAAAAAAAAAAAAAAAAAAAAAAAAAAAAAAAAAAAAA",
                            "AAAAAAAAAAAAAAAAAAAAAAAAAAAAAAAAAAAAAAA", "AAAAAAAAAAAAAAAAAAAAAAAAAAAAAAAAAAAAAAA",
                            "AAAAAAAAAAAAAAAAAAAAAAAAAAAAAAAAAAAAAAA", "AAAADAAAAAAAAAAAAAAAAAAAAAAAAAAAAADAAAA",
                            "AAABEAAAAAAAAAAAAAAAAAAAAAAAAAAAAAEBAAA", "AAAADAAAAAAAAAAAAAAAAAAAAAAAAAAAAADAAAA",
                            "AAAAAAAAAAAAAAAAAAAAAAAAAAAAAAAAAAAAAAA", "AAAAAAAAAAAAAAAAAAAAAAAAAAAAAAAAAAAAAAA",
                            "AAAAAAAAAAAAAAAAAAAAAAAAAAAAAAAAAAAAAAA", "AAAAAAAAAAAAAAAAAAAAAAAAAAAAAAAAAAAAAAA",
                            "AAAAAAAAAAAAAAAAAAAAAAAAAAAAAAAAAAAAAAA", "AAAAAAAAAAAAAAAAAAAAAAAAAAAAAAAAAAAAAAA",
                            "AAAAAAAAAAAAAAAAAAAAAAAAAAAAAAAAAAAAAAA", "AAAAAAAAAAAAAAAAAAAAAAAAAAAAAAAAAAAAAAA",
                            "AAAAAAAAAAAAAAAAAAAAAAAAAAAAAAAAAAAAAAA", "AAAAAAAAAAAAAAAAAAAAAAAAAAAAAAAAAAAAAAA",
                            "AAAAAAAAAAAAAAAAAAAAAAAAAAAAAAAAAAAAAAA", "AAAAAAAAAAAAAAAAAAAAAAAAAAAAAAAAAAAAAAA",
                            "AAAAAAAAAAAAAAAAAAAAAAAAAAAAAAAAAAAAAAA", "AAAAAAAAAAAAAAAAAAAAAAAAAAAAAAAAAAAAAAA",
                            "AAAAAAAAAAAAAAAAAAAAAAAAAAAAAAAAAAAAAAA", "AAAAAAAAAAAAAAAAAAAAAAAAAAAAAAAAAAAAAAA",
                            "AAAAAAAAAAAAAAAAAAADAAAAAAAAAAAAAAAAAAA", "AAAAAAAAAAAAAAAAAAAAAAAAAAAAAAAAAAAAAAA")
                    .aisle("AAAAAAAAAAAAAAAAAAAAAAAAAAAAAAAAAAAAAAA", "AAAAAAAAAAAAAAAAAAAAAAAAAAAAAAAAAAAAAAA",
                            "AAAAAAAAAAAAAAAAAAADAAAAAAAAAAAAAAAAAAA", "AAAAAAAAAAAAAAAAAAAAAAAAAAAAAAAAAAAAAAA",
                            "AAAAAAAAAAAAAAAAAAAAAAAAAAAAAAAAAAAAAAA", "AAAAAAAAAAAAAAAAAAAAAAAAAAAAAAAAAAAAAAA",
                            "AAAAAAAAAAAAAAAAAAAAAAAAAAAAAAAAAAAAAAA", "AAAAAAAAAAAAAAAAAAAAAAAAAAAAAAAAAAAAAAA",
                            "AAAAAAAAAAAAAAAAAAAAAAAAAAAAAAAAAAAAAAA", "AAAAAAAAAAAAAAAAAAAAAAAAAAAAAAAAAAAAAAA",
                            "AAAAAAAAAAAAAAAAAAAAAAAAAAAAAAAAAAAAAAA", "AAAAAAAAAAAAAAAAAAAAAAAAAAAAAAAAAAAAAAA",
                            "AAAAAAAAAAAAAAAAAAAAAAAAAAAAAAAAAAAAAAA", "AAAAAAAAAAAAAAAAAAAAAAAAAAAAAAAAAAAAAAA",
                            "AAAAAAAAAAAAAAAAAAAAAAAAAAAAAAAAAAAAAAA", "AAAAAAAAAAAAAAAAAAAAAAAAAAAAAAAAAAAAAAA",
                            "AAAAAAAAAAAAAAAAAAAAAAAAAAAAAAAAAAAAAAA", "AAAAAAAAAAAAAAAAAAAAAAAAAAAAAAAAAAAAAAA",
                            "AAAAAAAAAAAAAAAAAAAAAAAAAAAAAAAAAAAAAAA", "AAAADAAAAAAAAAAAAAAAAAAAAAAAAAAAAADAAAA",
                            "AAABEAAAAAAAAAAAAAAAAAAAAAAAAAAAAAEBAAA", "AAAADAAAAAAAAAAAAAAAAAAAAAAAAAAAAADAAAA",
                            "AAAAAAAAAAAAAAAAAAAAAAAAAAAAAAAAAAAAAAA", "AAAAAAAAAAAAAAAAAAAAAAAAAAAAAAAAAAAAAAA",
                            "AAAAAAAAAAAAAAAAAAAAAAAAAAAAAAAAAAAAAAA", "AAAAAAAAAAAAAAAAAAAAAAAAAAAAAAAAAAAAAAA",
                            "AAAAAAAAAAAAAAAAAAAAAAAAAAAAAAAAAAAAAAA", "AAAAAAAAAAAAAAAAAAAAAAAAAAAAAAAAAAAAAAA",
                            "AAAAAAAAAAAAAAAAAAAAAAAAAAAAAAAAAAAAAAA", "AAAAAAAAAAAAAAAAAAAAAAAAAAAAAAAAAAAAAAA",
                            "AAAAAAAAAAAAAAAAAAAAAAAAAAAAAAAAAAAAAAA", "AAAAAAAAAAAAAAAAAAAAAAAAAAAAAAAAAAAAAAA",
                            "AAAAAAAAAAAAAAAAAAAAAAAAAAAAAAAAAAAAAAA", "AAAAAAAAAAAAAAAAAAAAAAAAAAAAAAAAAAAAAAA",
                            "AAAAAAAAAAAAAAAAAAAAAAAAAAAAAAAAAAAAAAA", "AAAAAAAAAAAAAAAAAAAAAAAAAAAAAAAAAAAAAAA",
                            "AAAAAAAAAAAAAAAAAAAAAAAAAAAAAAAAAAAAAAA", "AAAAAAAAAAAAAAAAAAAAAAAAAAAAAAAAAAAAAAA",
                            "AAAAAAAAAAAAAAAAAAADAAAAAAAAAAAAAAAAAAA", "AAAAAAAAAAAAAAAAAAAAAAAAAAAAAAAAAAAAAAA")
                    .aisle("AAAAAAAAAAAAAAAAAAAAAAAAAAAAAAAAAAAAAAA", "AAAAAAAAAAAAAAAAAAAAAAAAAAAAAAAAAAAAAAA",
                            "AAAAAAAAAAAAAAAAAAADAAAAAAAAAAAAAAAAAAA", "AAAAAAAAAAAAAAAAAAAAAAAAAAAAAAAAAAAAAAA",
                            "AAAAAAAAAAAAAAAAAAAAAAAAAAAAAAAAAAAAAAA", "AAAAAAAAAAAAAAAAAAAAAAAAAAAAAAAAAAAAAAA",
                            "AAAAAAAAAAAAAAAAAAAAAAAAAAAAAAAAAAAAAAA", "AAAAAAAAAAAAAAAAAAAAAAAAAAAAAAAAAAAAAAA",
                            "AAAAAAAAAAAAAAAAAAAAAAAAAAAAAAAAAAAAAAA", "AAAAAAAAAAAAAAAAAAAAAAAAAAAAAAAAAAAAAAA",
                            "AAAAAAAAAAAAAAAAAAAAAAAAAAAAAAAAAAAAAAA", "AAAAAAAAAAAAAAAAAAAAAAAAAAAAAAAAAAAAAAA",
                            "AAAAAAAAAAAAAAAAAAAAAAAAAAAAAAAAAAAAAAA", "AAAAAAAAAAAAAAAAAAAAAAAAAAAAAAAAAAAAAAA",
                            "AAAAAAAAAAAAAAAAAAAAAAAAAAAAAAAAAAAAAAA", "AAAAAAAAAAAAAAAAAAAAAAAAAAAAAAAAAAAAAAA",
                            "AAAAAAAAAAAAAAAAAAAAAAAAAAAAAAAAAAAAAAA", "AAAAAAAAAAAAAAAAAAAAAAAAAAAAAAAAAAAAAAA",
                            "AAAAAAAAAAAAAAAAAAAAAAAAAAAAAAAAAAAAAAA", "AAAAADAAAAAAAAAAAAAAAAAAAAAAAAAAADAAAAA",
                            "AAAABEAAAAAAAAAAAAAAAAAAAAAAAAAAAEBAAAA", "AAAAADAAAAAAAAAAAAAAAAAAAAAAAAAAADAAAAA",
                            "AAAAAAAAAAAAAAAAAAAAAAAAAAAAAAAAAAAAAAA", "AAAAAAAAAAAAAAAAAAAAAAAAAAAAAAAAAAAAAAA",
                            "AAAAAAAAAAAAAAAAAAAAAAAAAAAAAAAAAAAAAAA", "AAAAAAAAAAAAAAAAAAAAAAAAAAAAAAAAAAAAAAA",
                            "AAAAAAAAAAAAAAAAAAAAAAAAAAAAAAAAAAAAAAA", "AAAAAAAAAAAAAAAAAAAAAAAAAAAAAAAAAAAAAAA",
                            "AAAAAAAAAAAAAAAAAAAAAAAAAAAAAAAAAAAAAAA", "AAAAAAAAAAAAAAAAAAAAAAAAAAAAAAAAAAAAAAA",
                            "AAAAAAAAAAAAAAAAAAAAAAAAAAAAAAAAAAAAAAA", "AAAAAAAAAAAAAAAAAAAAAAAAAAAAAAAAAAAAAAA",
                            "AAAAAAAAAAAAAAAAAAAAAAAAAAAAAAAAAAAAAAA", "AAAAAAAAAAAAAAAAAAAAAAAAAAAAAAAAAAAAAAA",
                            "AAAAAAAAAAAAAAAAAAAAAAAAAAAAAAAAAAAAAAA", "AAAAAAAAAAAAAAAAAAAAAAAAAAAAAAAAAAAAAAA",
                            "AAAAAAAAAAAAAAAAAAAAAAAAAAAAAAAAAAAAAAA", "AAAAAAAAAAAAAAAAAAAAAAAAAAAAAAAAAAAAAAA",
                            "AAAAAAAAAAAAAAAAAAADAAAAAAAAAAAAAAAAAAA", "AAAAAAAAAAAAAAAAAAAAAAAAAAAAAAAAAAAAAAA")
                    .aisle("AAAAAAAAAAAAAAAAAAAAAAAAAAAAAAAAAAAAAAA", "AAAAAAAAAAAAAAAAAAAAAAAAAAAAAAAAAAAAAAA",
                            "AAAAAAAAAAAAAAAAAAAAAAAAAAAAAAAAAAAAAAA", "AAAAAAAAAAAAAAAAAAAAAAAAAAAAAAAAAAAAAAA",
                            "AAAAAAAAAAAAAAAAAAAAAAAAAAAAAAAAAAAAAAA", "AAAAAAAAAAAAAAAAAAAAAAAAAAAAAAAAAAAAAAA",
                            "AAAAAAAAAAAAAAAAAAAAAAAAAAAAAAAAAAAAAAA", "AAAAAAAAAAAAAAAAAAAAAAAAAAAAAAAAAAAAAAA",
                            "AAAAAAAAAAAAAAAAAAAAAAAAAAAAAAAAAAAAAAA", "AAAAAAAAAAAAAAAAAAAAAAAAAAAAAAAAAAAAAAA",
                            "AAAAAAAAAAAAAAAAAAAAAAAAAAAAAAAAAAAAAAA", "AAAAAAAAAAAAAAAAAAAAAAAAAAAAAAAAAAAAAAA",
                            "AAAAAAAAAAAAAAAAAAAAAAAAAAAAAAAAAAAAAAA", "AAAAAAAAAAAAAAAAAAAAAAAAAAAAAAAAAAAAAAA",
                            "AAAAAAAAAAAAAAAAAAAAAAAAAAAAAAAAAAAAAAA", "AAAAAAAAAAAAAAAAAAAAAAAAAAAAAAAAAAAAAAA",
                            "AAAAAAAAAAAAAAAAAAAAAAAAAAAAAAAAAAAAAAA", "AAAAADAAAAAAAAAAAAAAAAAAAAAAAAAAADAAAAA",
                            "AAAAADAAAAAAAAAAAAAAAAAAAAAAAAAAADAAAAA", "AAAAADAAAAAAAAAAAAAAAAAAAAAAAAAAADAAAAA",
                            "AAAAADFAAAAAAAAAAAAAAAAAAAAAAAAAFDAAAAA", "AAAAADAAAAAAAAAAAAAAAAAAAAAAAAAAADAAAAA",
                            "AAAAADAAAAAAAAAAAAAAAAAAAAAAAAAAADAAAAA", "AAAAADAAAAAAAAAAAAAAAAAAAAAAAAAAADAAAAA",
                            "AAAAAAAAAAAAAAAAAAAAAAAAAAAAAAAAAAAAAAA", "AAAAAAAAAAAAAAAAAAAAAAAAAAAAAAAAAAAAAAA",
                            "AAAAAAAAAAAAAAAAAAAAAAAAAAAAAAAAAAAAAAA", "AAAAAAAAAAAAAAAAAAAAAAAAAAAAAAAAAAAAAAA",
                            "AAAAAAAAAAAAAAAAAAAAAAAAAAAAAAAAAAAAAAA", "AAAAAAAAAAAAAAAAAAAAAAAAAAAAAAAAAAAAAAA",
                            "AAAAAAAAAAAAAAAAAAAAAAAAAAAAAAAAAAAAAAA", "AAAAAAAAAAAAAAAAAAAAAAAAAAAAAAAAAAAAAAA",
                            "AAAAAAAAAAAAAAAAAAAAAAAAAAAAAAAAAAAAAAA", "AAAAAAAAAAAAAAAAAAAAAAAAAAAAAAAAAAAAAAA",
                            "AAAAAAAAAAAAAAAAAAAAAAAAAAAAAAAAAAAAAAA", "AAAAAAAAAAAAAAAAAAAAAAAAAAAAAAAAAAAAAAA",
                            "AAAAAAAAAAAAAAAAAAAAAAAAAAAAAAAAAAAAAAA", "AAAAAAAAAAAAAAAAAAAAAAAAAAAAAAAAAAAAAAA",
                            "AAAAAAAAAAAAAAAAAAAAAAAAAAAAAAAAAAAAAAA", "AAAAAAAAAAAAAAAAAAAAAAAAAAAAAAAAAAAAAAA")
                    .aisle("AAAAAAAAAAAAAAAAAAAAAAAAAAAAAAAAAAAAAAA", "AAAAAAAAAAAAAAAAAAAAAAAAAAAAAAAAAAAAAAA",
                            "AAAAAAAAAAAAAAAAAAAAAAAAAAAAAAAAAAAAAAA", "AAAAAAAAAAAAAAAAAAAAAAAAAAAAAAAAAAAAAAA",
                            "AAAAAAAAAAAAAAAAAAAAAAAAAAAAAAAAAAAAAAA", "AAAAAAAAAAAAAAAAAAAAAAAAAAAAAAAAAAAAAAA",
                            "AAAAAAAAAAAAAAAAAAAAAAAAAAAAAAAAAAAAAAA", "AAAAAAAAAAAAAAAAAAAAAAAAAAAAAAAAAAAAAAA",
                            "AAAAAAAAAAAAAAAAAAAAAAAAAAAAAAAAAAAAAAA", "AAAAAAAAAAAAAAAAAAAAAAAAAAAAAAAAAAAAAAA",
                            "AAAAAAAAAAAAAAAAAAAAAAAAAAAAAAAAAAAAAAA", "AAAAAAAAAAAAAAAAAAAAAAAAAAAAAAAAAAAAAAA",
                            "AAAAAAAAAAAAAAAAAAAAAAAAAAAAAAAAAAAAAAA", "AAAAAAAAAAAAAAAAAAAAAAAAAAAAAAAAAAAAAAA",
                            "AAAAAADAAAAAAAAAAAAAAAAAAAAAAAAADAAAAAA", "AAAAAADAAAAAAAAAAAAAAAAAAAAAAAAADAAAAAA",
                            "AAAAAADAAAAAAAAAAAAAAAAAAAAAAAAADAAAAAA", "AAAAAADAAAAAAAAAAAAAAAAAAAAAAAAADAAAAAA",
                            "AAAAAADAAAAAAAAAAAAAAAAAAAAAAAAADAAAAAA", "AAAAAADAAAAAAAAAAAAAAAAAAAAAAAAADAAAAAA",
                            "AAAAAAAFAAAAAAAAAAAAAAAAAAAAAAAFAAAAAAA", "AAAAAADAAAAAAAAAAAAAAAAAAAAAAAAADAAAAAA",
                            "AAAAAADAAAAAAAAAAAAAAAAAAAAAAAAADAAAAAA", "AAAAAADAAAAAAAAAAAAAAAAAAAAAAAAADAAAAAA",
                            "AAAAAADAAAAAAAAAAAAAAAAAAAAAAAAADAAAAAA", "AAAAAADAAAAAAAAAAAAAAAAAAAAAAAAADAAAAAA",
                            "AAAAAADAAAAAAAAAAAAAAAAAAAAAAAAADAAAAAA", "AAAAAAAAAAAAAAAAAAAAAAAAAAAAAAAAAAAAAAA",
                            "AAAAAAAAAAAAAAAAAAAAAAAAAAAAAAAAAAAAAAA", "AAAAAAAAAAAAAAAAAAAAAAAAAAAAAAAAAAAAAAA",
                            "AAAAAAAAAAAAAAAAAAAAAAAAAAAAAAAAAAAAAAA", "AAAAAAAAAAAAAAAAAAAAAAAAAAAAAAAAAAAAAAA",
                            "AAAAAAAAAAAAAAAAAAAAAAAAAAAAAAAAAAAAAAA", "AAAAAAAAAAAAAAAAAAAAAAAAAAAAAAAAAAAAAAA",
                            "AAAAAAAAAAAAAAAAAAAAAAAAAAAAAAAAAAAAAAA", "AAAAAAAAAAAAAAAAAAAAAAAAAAAAAAAAAAAAAAA",
                            "AAAAAAAAAAAAAAAAAAAAAAAAAAAAAAAAAAAAAAA", "AAAAAAAAAAAAAAAAAAAAAAAAAAAAAAAAAAAAAAA",
                            "AAAAAAAAAAAAAAAAAAAAAAAAAAAAAAAAAAAAAAA", "AAAAAAAAAAAAAAAAAAAAAAAAAAAAAAAAAAAAAAA")
                    .aisle("AAAAAAAAAAAAAAAAAAAAAAAAAAAAAAAAAAAAAAA", "AAAAAAAAAAAAAAAAAAAAAAAAAAAAAAAAAAAAAAA",
                            "AAAAAAAAAAAAAAAAAAAAAAAAAAAAAAAAAAAAAAA", "AAAAAAAAAAAAAAAAAAAAAAAAAAAAAAAAAAAAAAA",
                            "AAAAAAAAAAAAAAAAAAAAAAAAAAAAAAAAAAAAAAA", "AAAAAAAAAAAAAAAAAAAAAAAAAAAAAAAAAAAAAAA",
                            "AAAAAAAAAAAAAAAAAAAAAAAAAAAAAAAAAAAAAAA", "AAAAAAAAAAAAAAAAAAAAAAAAAAAAAAAAAAAAAAA",
                            "AAAAAAAAAAAAAAAAAAAAAAAAAAAAAAAAAAAAAAA", "AAAAAAAAAAAAAAAAAAAAAAAAAAAAAAAAAAAAAAA",
                            "AAAAAAAAAAAAAAAAAAAAAAAAAAAAAAAAAAAAAAA", "AAAAAAAAAAAAAAAAAAAAAAAAAAAAAAAAAAAAAAA",
                            "AAAAAAAAAAAAAAAAAAAAAAAAAAAAAAAAAAAAAAA", "AAAAAAAAAAAAAAAAAAAAAAAAAAAAAAAAAAAAAAA",
                            "AAAAAAAAAAAAAAAAAAAAAAAAAAAAAAAAAAAAAAA", "AAAAAAAAAAAAAAAAAAAAAAAAAAAAAAAAAAAAAAA",
                            "AAAAAAAAAAAAAAAAAAAAAAAAAAAAAAAAAAAAAAA", "AAAAAAADAAAAAAAAAAAAAAAAAAAAAAADAAAAAAA",
                            "AAAAAAADAAAAAAAAAAAAAAAAAAAAAAADAAAAAAA", "AAAAAAADDAAAAAAAAAAAAAAAAAAAAADDAAAAAAA",
                            "AAAAAAADEAAAAAAAAAAAAAAAAAAAAAEDAAAAAAA", "AAAAAAADDAAAAAAAAAAAAAAAAAAAAADDAAAAAAA",
                            "AAAAAAADAAAAAAAAAAAAAAAAAAAAAAADAAAAAAA", "AAAAAAADAAAAAAAAAAAAAAAAAAAAAAADAAAAAAA",
                            "AAAAAAAAAAAAAAAAAAAAAAAAAAAAAAAAAAAAAAA", "AAAAAAAAAAAAAAAAAAAAAAAAAAAAAAAAAAAAAAA",
                            "AAAAAAAAAAAAAAAAAAAAAAAAAAAAAAAAAAAAAAA", "AAAAAAAAAAAAAAAAAAAAAAAAAAAAAAAAAAAAAAA",
                            "AAAAAAAAAAAAAAAAAAAAAAAAAAAAAAAAAAAAAAA", "AAAAAAAAAAAAAAAAAAAAAAAAAAAAAAAAAAAAAAA",
                            "AAAAAAAAAAAAAAAAAAAAAAAAAAAAAAAAAAAAAAA", "AAAAAAAAAAAAAAAAAAAAAAAAAAAAAAAAAAAAAAA",
                            "AAAAAAAAAAAAAAAAAAAAAAAAAAAAAAAAAAAAAAA", "AAAAAAAAAAAAAAAAAAAAAAAAAAAAAAAAAAAAAAA",
                            "AAAAAAAAAAAAAAAAAAAAAAAAAAAAAAAAAAAAAAA", "AAAAAAAAAAAAAAAAAAAAAAAAAAAAAAAAAAAAAAA",
                            "AAAAAAAAAAAAAAAAAAAAAAAAAAAAAAAAAAAAAAA", "AAAAAAAAAAAAAAAAAAAAAAAAAAAAAAAAAAAAAAA",
                            "AAAAAAAAAAAAAAAAAAAAAAAAAAAAAAAAAAAAAAA", "AAAAAAAAAAAAAAAAAAAAAAAAAAAAAAAAAAAAAAA")
                    .aisle("AAAAAAAAAAAAAAAAAAAAAAAAAAAAAAAAAAAAAAA", "AAAAAAAAAAAAAAAAAAAAAAAAAAAAAAAAAAAAAAA",
                            "AAAAAAAAAAAAAAAAAAAAAAAAAAAAAAAAAAAAAAA", "AAAAAAAAAAAAAAAAAAAAAAAAAAAAAAAAAAAAAAA",
                            "AAAAAAAAAAAAAAAAAAAAAAAAAAAAAAAAAAAAAAA", "AAAAAAAAAAAAAAAAAAAAAAAAAAAAAAAAAAAAAAA",
                            "AAAAAAAAAAAAAAAAAAAAAAAAAAAAAAAAAAAAAAA", "AAAAAAAAAAAAAAAAAAAAAAAAAAAAAAAAAAAAAAA",
                            "AAAAAAAAAAAAAAAAAAAAAAAAAAAAAAAAAAAAAAA", "AAAAAAAAAAAAAAAAAAAAAAAAAAAAAAAAAAAAAAA",
                            "AAAAAAAAAAAAAAAAAAAAAAAAAAAAAAAAAAAAAAA", "AAAAAAAAAAAAAAAAAAAAAAAAAAAAAAAAAAAAAAA",
                            "AAAAAAAAAAAAAAAAAAAAAAAAAAAAAAAAAAAAAAA", "AAAAAAAAAAAAAAAAAAAAAAAAAAAAAAAAAAAAAAA",
                            "AAAAAAAAAAAAAAAAAAAAAAAAAAAAAAAAAAAAAAA", "AAAAAAAAAAAAAAAAAAAAAAAAAAAAAAAAAAAAAAA",
                            "AAAAAAAAAAAAAAAAAAAAAAAAAAAAAAAAAAAAAAA", "AAAAAAAAAAAAAAAAAAAAAAAAAAAAAAAAAAAAAAA",
                            "AAAAAAAAAAAAAAAAAAAAAAAAAAAAAAAAAAAAAAA", "AAAAAAAAADDAAAAAAAAAAAAAAAAADDAAAAAAAAA",
                            "AAAAAAAABEEAAAAAAAAAAAAAAAAAEEBAAAAAAAA", "AAAAAAAAADDAAAAAAAAAAAAAAAAADDAAAAAAAAA",
                            "AAAAAAAAAAAAAAAAAAAAAAAAAAAAAAAAAAAAAAA", "AAAAAAAAAAAAAAAAAAAAAAAAAAAAAAAAAAAAAAA",
                            "AAAAAAAAAAAAAAAAAAAAAAAAAAAAAAAAAAAAAAA", "AAAAAAAAAAAAAAAAAAAAAAAAAAAAAAAAAAAAAAA",
                            "AAAAAAAAAAAAAAAAAAAAAAAAAAAAAAAAAAAAAAA", "AAAAAAAAAAAAAAAAAAAAAAAAAAAAAAAAAAAAAAA",
                            "AAAAAAAAAAAAAAAAAAAAAAAAAAAAAAAAAAAAAAA", "AAAAAAAAAAAAAAAAAAAAAAAAAAAAAAAAAAAAAAA",
                            "AAAAAAAAAAAAAAAAAAAAAAAAAAAAAAAAAAAAAAA", "AAAAAAAAAAAAAAAAAAAAAAAAAAAAAAAAAAAAAAA",
                            "AAAAAAAAAAAAAAAAAAAAAAAAAAAAAAAAAAAAAAA", "AAAAAAAAAAAAAAAAAAAAAAAAAAAAAAAAAAAAAAA",
                            "AAAAAAAAAAAAAAAAAAAAAAAAAAAAAAAAAAAAAAA", "AAAAAAAAAAAAAAAAAAAAAAAAAAAAAAAAAAAAAAA",
                            "AAAAAAAAAAAAAAAAAAAAAAAAAAAAAAAAAAAAAAA", "AAAAAAAAAAAAAAAAAAAAAAAAAAAAAAAAAAAAAAA",
                            "AAAAAAAAAAAAAAAAAAAAAAAAAAAAAAAAAAAAAAA", "AAAAAAAAAAAAAAAAAAAAAAAAAAAAAAAAAAAAAAA")
                    .aisle("AAAAAAAAAAAAAAAAAAAAAAAAAAAAAAAAAAAAAAA", "AAAAAAAAAAAAAAAAAAAAAAAAAAAAAAAAAAAAAAA",
                            "AAAAAAAAAAAAAAAAAAAAAAAAAAAAAAAAAAAAAAA", "AAAAAAAAAAAAAAAAAAAAAAAAAAAAAAAAAAAAAAA",
                            "AAAAAAAAAAAAAAAAAAAAAAAAAAAAAAAAAAAAAAA", "AAAAAAAAAAAAAAAAAAAAAAAAAAAAAAAAAAAAAAA",
                            "AAAAAAAAAAAAAAAAAAAAAAAAAAAAAAAAAAAAAAA", "AAAAAAAAAAAAAAAAAAAAAAAAAAAAAAAAAAAAAAA",
                            "AAAAAAAAAAAAAAAAAAAAAAAAAAAAAAAAAAAAAAA", "AAAAAAAAAAAAAAAAAAAAAAAAAAAAAAAAAAAAAAA",
                            "AAAAAAAAAAAAAAAAAAAAAAAAAAAAAAAAAAAAAAA", "AAAAAAAAAAAAAAAAAAAAAAAAAAAAAAAAAAAAAAA",
                            "AAAAAAAAAAAAAAAAAAAAAAAAAAAAAAAAAAAAAAA", "AAAAAAAAAAAAAAAAAAAAAAAAAAAAAAAAAAAAAAA",
                            "AAAAAAAAAAAAAAAAAAAAAAAAAAAAAAAAAAAAAAA", "AAAAAAAAAAAAAAAAAAAAAAAAAAAAAAAAAAAAAAA",
                            "AAAAAAAAAAAAAAAAAAAAAAAAAAAAAAAAAAAAAAA", "AAAAAAAAAAAAAAAAAAAAAAAAAAAAAAAAAAAAAAA",
                            "AAAAAAAAAAAAAAAAAAAAAAAAAAAAAAAAAAAAAAA", "AAAAAAAAAAADDDAAAAAAAAAAADDDAAAAAAAAAAA",
                            "AAAAAAAAABBEEEAAAAAAAAAAAEEEBBAAAAAAAAA", "AAAAAAAAAAADDDAAAAAAAAAAADDDAAAAAAAAAAA",
                            "AAAAAAAAAAAAAAAAAAAAAAAAAAAAAAAAAAAAAAA", "AAAAAAAAAAAAAAAAAAAAAAAAAAAAAAAAAAAAAAA",
                            "AAAAAAAAAAAAAAAAAAAAAAAAAAAAAAAAAAAAAAA", "AAAAAAAAAAAAAAAAAAAAAAAAAAAAAAAAAAAAAAA",
                            "AAAAAAAAAAAAAAAAAAAAAAAAAAAAAAAAAAAAAAA", "AAAAAAAAAAAAAAAAAAAAAAAAAAAAAAAAAAAAAAA",
                            "AAAAAAAAAAAAAAAAAAAAAAAAAAAAAAAAAAAAAAA", "AAAAAAAAAAAAAAAAAAAAAAAAAAAAAAAAAAAAAAA",
                            "AAAAAAAAAAAAAAAAAAAAAAAAAAAAAAAAAAAAAAA", "AAAAAAAAAAAAAAAAAAAAAAAAAAAAAAAAAAAAAAA",
                            "AAAAAAAAAAAAAAAAAAAAAAAAAAAAAAAAAAAAAAA", "AAAAAAAAAAAAAAAAAAAAAAAAAAAAAAAAAAAAAAA",
                            "AAAAAAAAAAAAAAAAAAAAAAAAAAAAAAAAAAAAAAA", "AAAAAAAAAAAAAAAAAAAAAAAAAAAAAAAAAAAAAAA",
                            "AAAAAAAAAAAAAAAAAAAAAAAAAAAAAAAAAAAAAAA", "AAAAAAAAAAAAAAAAAAAAAAAAAAAAAAAAAAAAAAA",
                            "AAAAAAAAAAAAAAAAAAAAAAAAAAAAAAAAAAAAAAA", "AAAAAAAAAAAAAAAAAAAAAAAAAAAAAAAAAAAAAAA")
                    .aisle("AAAAAAAAAAAAAAAAAAAAAAAAAAAAAAAAAAAAAAA", "AAAAAAAAAAAAAAAAAAAAAAAAAAAAAAAAAAAAAAA",
                            "AAAAAAAAAAAAAAAAAAAAAAAAAAAAAAAAAAAAAAA", "AAAAAAAAAAAAAAAAAAAAAAAAAAAAAAAAAAAAAAA",
                            "AAAAAAAAAAAAAAAAAAAAAAAAAAAAAAAAAAAAAAA", "AAAAAAAAAAAAAAAAAAAAAAAAAAAAAAAAAAAAAAA",
                            "AAAAAAAAAAAAAAAAAAAAAAAAAAAAAAAAAAAAAAA", "AAAAAAAAAAAAAAAAAAAAAAAAAAAAAAAAAAAAAAA",
                            "AAAAAAAAAAAAAAAAAAAAAAAAAAAAAAAAAAAAAAA", "AAAAAAAAAAAAAAAAAAAAAAAAAAAAAAAAAAAAAAA",
                            "AAAAAAAAAAAAAAAAAAAAAAAAAAAAAAAAAAAAAAA", "AAAAAAAAAAAAAAAAAAAAAAAAAAAAAAAAAAAAAAA",
                            "AAAAAAAAAAAAAAAAAAAAAAAAAAAAAAAAAAAAAAA", "AAAAAAAAAAAAAAAAAAAAAAAAAAAAAAAAAAAAAAA",
                            "AAAAAAAAAAAAAAAAAAAAAAAAAAAAAAAAAAAAAAA", "AAAAAAAAAAAAAAAAAAAAAAAAAAAAAAAAAAAAAAA",
                            "AAAAAAAAAAAAAAAAAAAAAAAAAAAAAAAAAAAAAAA", "AAAAAAAAAAAAAAAAAAAAAAAAAAAAAAAAAAAAAAA",
                            "AAAAAAAAAAAAAAAAAAAAAAAAAAAAAAAAAAAAAAA", "AAAAAAAAAAAAAADDDDDDDDDDDAAAAAAAAAAAAAA",
                            "AAAAAAAAAAABBBEEEDEBEDEEEBBBAAAAAAAAAAA", "AAAAAAAAAAAAAADDDDDDDDDDDAAAAAAAAAAAAAA",
                            "AAAAAAAAAAAAAAAAAAAAAAAAAAAAAAAAAAAAAAA", "AAAAAAAAAAAAAAAAAAAAAAAAAAAAAAAAAAAAAAA",
                            "AAAAAAAAAAAAAAAAAAAAAAAAAAAAAAAAAAAAAAA", "AAAAAAAAAAAAAAAAAAAAAAAAAAAAAAAAAAAAAAA",
                            "AAAAAAAAAAAAAAAAAAAAAAAAAAAAAAAAAAAAAAA", "AAAAAAAAAAAAAAAAAAAAAAAAAAAAAAAAAAAAAAA",
                            "AAAAAAAAAAAAAAAAAAAAAAAAAAAAAAAAAAAAAAA", "AAAAAAAAAAAAAAAAAAAAAAAAAAAAAAAAAAAAAAA",
                            "AAAAAAAAAAAAAAAAAAAAAAAAAAAAAAAAAAAAAAA", "AAAAAAAAAAAAAAAAAAAAAAAAAAAAAAAAAAAAAAA",
                            "AAAAAAAAAAAAAAAAAAAAAAAAAAAAAAAAAAAAAAA", "AAAAAAAAAAAAAAAAAAAAAAAAAAAAAAAAAAAAAAA",
                            "AAAAAAAAAAAAAAAAAAAAAAAAAAAAAAAAAAAAAAA", "AAAAAAAAAAAAAAAAAAAAAAAAAAAAAAAAAAAAAAA",
                            "AAAAAAAAAAAAAAAAAAAAAAAAAAAAAAAAAAAAAAA", "AAAAAAAAAAAAAAAAAAAAAAAAAAAAAAAAAAAAAAA",
                            "AAAAAAAAAAAAAAAAAAAAAAAAAAAAAAAAAAAAAAA", "AAAAAAAAAAAAAAAAAAAAAAAAAAAAAAAAAAAAAAA")
                    .aisle("AAAAAAAAAAAAAAAAAAAAAAAAAAAAAAAAAAAAAAA", "AAAAAAAAAAAAAAAAAAAAAAAAAAAAAAAAAAAAAAA",
                            "AAAAAAAAAAAAAAAAAAAAAAAAAAAAAAAAAAAAAAA", "AAAAAAAAAAAAAAAAAAAAAAAAAAAAAAAAAAAAAAA",
                            "AAAAAAAAAAAAAAAAAAAAAAAAAAAAAAAAAAAAAAA", "AAAAAAAAAAAAAAAAAAAAAAAAAAAAAAAAAAAAAAA",
                            "AAAAAAAAAAAAAAAAAAAAAAAAAAAAAAAAAAAAAAA", "AAAAAAAAAAAAAAAAAAAAAAAAAAAAAAAAAAAAAAA",
                            "AAAAAAAAAAAAAAAAAAAAAAAAAAAAAAAAAAAAAAA", "AAAAAAAAAAAAAAAAAAAAAAAAAAAAAAAAAAAAAAA",
                            "AAAAAAAAAAAAAAAAAAAAAAAAAAAAAAAAAAAAAAA", "AAAAAAAAAAAAAAAAAAAAAAAAAAAAAAAAAAAAAAA",
                            "AAAAAAAAAAAAAAAAAAAAAAAAAAAAAAAAAAAAAAA", "AAAAAAAAAAAAAAAAAAAAAAAAAAAAAAAAAAAAAAA",
                            "AAAAAAAAAAAAAAAAAAAAAAAAAAAAAAAAAAAAAAA", "AAAAAAAAAAAAAAAAAAADAAAAAAAAAAAAAAAAAAA",
                            "AAAAAAAAAAAAAAAAAAADAAAAAAAAAAAAAAAAAAA", "AAAAAAAAAAAAAAAAAAADAAAAAAAAAAAAAAAAAAA",
                            "AAAAAAAAAAAAAAAAAADDDAAAAAAAAAAAAAAAAAA", "AAAAAAAAAAAAAAAAADDEDDAAAAAAAAAAAAAAAAA",
                            "AAAAAAAAAAAAAABBBDEBEDBBBAAAAAAAAAAAAAA", "AAAAAAAAAAAAAAAAADDEDDAAAAAAAAAAAAAAAAA",
                            "AAAAAAAAAAAAAAAAAADDDAAAAAAAAAAAAAAAAAA", "AAAAAAAAAAAAAAAAAAADAAAAAAAAAAAAAAAAAAA",
                            "AAAAAAAAAAAAAAAAAAADAAAAAAAAAAAAAAAAAAA", "AAAAAAAAAAAAAAAAAAADAAAAAAAAAAAAAAAAAAA",
                            "AAAAAAAAAAAAAAAAAAADAAAAAAAAAAAAAAAAAAA", "AAAAAAAAAAAAAAAAAAAAAAAAAAAAAAAAAAAAAAA",
                            "AAAAAAAAAAAAAAAAAAAAAAAAAAAAAAAAAAAAAAA", "AAAAAAAAAAAAAAAAAAAAAAAAAAAAAAAAAAAAAAA",
                            "AAAAAAAAAAAAAAAAAAAAAAAAAAAAAAAAAAAAAAA", "AAAAAAAAAAAAAAAAAAAAAAAAAAAAAAAAAAAAAAA",
                            "AAAAAAAAAAAAAAAAAAAAAAAAAAAAAAAAAAAAAAA", "AAAAAAAAAAAAAAAAAAAAAAAAAAAAAAAAAAAAAAA",
                            "AAAAAAAAAAAAAAAAAAAAAAAAAAAAAAAAAAAAAAA", "AAAAAAAAAAAAAAAAAAAAAAAAAAAAAAAAAAAAAAA",
                            "AAAAAAAAAAAAAAAAAAAAAAAAAAAAAAAAAAAAAAA", "AAAAAAAAAAAAAAAAAAAAAAAAAAAAAAAAAAAAAAA",
                            "AAAAAAAAAAAAAAAAAAAAAAAAAAAAAAAAAAAAAAA", "AAAAAAAAAAAAAAAAAAAAAAAAAAAAAAAAAAAAAAA")
                    .aisle("AAAAAAAAAAAAAAAAAAAAAAAAAAAAAAAAAAAAAAA", "AAAAAAAAAAAAAAAAAAAAAAAAAAAAAAAAAAAAAAA",
                            "AAAAAAAAAAAAAAAAAAAAAAAAAAAAAAAAAAAAAAA", "AAAAAAAAAAAAAAAAAAAAAAAAAAAAAAAAAAAAAAA",
                            "AAAAAAAAAAAAAAAAAAAAAAAAAAAAAAAAAAAAAAA", "AAAAAAAAAAAAAAAAAAAAAAAAAAAAAAAAAAAAAAA",
                            "AAAAAAAAAAAAAAAAAAAAAAAAAAAAAAAAAAAAAAA", "AAAAAAAAAAAAAAAAAAAAAAAAAAAAAAAAAAAAAAA",
                            "AAAAAAAAAAAAAAAAAAAAAAAAAAAAAAAAAAAAAAA", "AAAAAAAAAAAAAAAAAAAAAAAAAAAAAAAAAAAAAAA",
                            "AAAAAAAAAAAAAAAAAAAAAAAAAAAAAAAAAAAAAAA", "AAAAAAAAAAAAAAAAAAAAAAAAAAAAAAAAAAAAAAA",
                            "AAAAAAAAAAAAAAAAAAAAAAAAAAAAAAAAAAAAAAA", "AAAAAAAAAAAAAAAAAAAAAAAAAAAAAAAAAAAAAAA",
                            "AAAAAAAAAAAAAAAAAAAAAAAAAAAAAAAAAAAAAAA", "AAAAAAAAAAAAAAAAAAAAAAAAAAAAAAAAAAAAAAA",
                            "AAAAAAAAAAAAAAAAAAAAAAAAAAAAAAAAAAAAAAA", "AAAAAAAAAAAAAAAAAAAAAAAAAAAAAAAAAAAAAAA",
                            "AAAAAAAAAAAAAAAAAAAAAAAAAAAAAAAAAAAAAAA", "AAAAAAAAAAAAAAAAAAAAAAAAAAAAAAAAAAAAAAA",
                            "AAAAAAAAAAAAAAAABDABADBAAAAAAAAAAAAAAAA", "AAAAAAAAAAAAAAAAAAAAAAAAAAAAAAAAAAAAAAA",
                            "AAAAAAAAAAAAAAAAAAAAAAAAAAAAAAAAAAAAAAA", "AAAAAAAAAAAAAAAAAAAAAAAAAAAAAAAAAAAAAAA",
                            "AAAAAAAAAAAAAAAAAAAAAAAAAAAAAAAAAAAAAAA", "AAAAAAAAAAAAAAAAAAAAAAAAAAAAAAAAAAAAAAA",
                            "AAAAAAAAAAAAAAAAAAAAAAAAAAAAAAAAAAAAAAA", "AAAAAAAAAAAAAAAAAAAAAAAAAAAAAAAAAAAAAAA",
                            "AAAAAAAAAAAAAAAAAAAAAAAAAAAAAAAAAAAAAAA", "AAAAAAAAAAAAAAAAAAAAAAAAAAAAAAAAAAAAAAA",
                            "AAAAAAAAAAAAAAAAAAAAAAAAAAAAAAAAAAAAAAA", "AAAAAAAAAAAAAAAAAAAAAAAAAAAAAAAAAAAAAAA",
                            "AAAAAAAAAAAAAAAAAAAAAAAAAAAAAAAAAAAAAAA", "AAAAAAAAAAAAAAAAAAAAAAAAAAAAAAAAAAAAAAA",
                            "AAAAAAAAAAAAAAAAAAAAAAAAAAAAAAAAAAAAAAA", "AAAAAAAAAAAAAAAAAAAAAAAAAAAAAAAAAAAAAAA",
                            "AAAAAAAAAAAAAAAAAAAAAAAAAAAAAAAAAAAAAAA", "AAAAAAAAAAAAAAAAAAAAAAAAAAAAAAAAAAAAAAA",
                            "AAAAAAAAAAAAAAAAAAAAAAAAAAAAAAAAAAAAAAA", "AAAAAAAAAAAAAAAAAAAAAAAAAAAAAAAAAAAAAAA")
                    .aisle("AAAAAAAAAAAAAAAAAAAAAAAAAAAAAAAAAAAAAAA", "AAAAAAAAAAAAAAAAAAAAAAAAAAAAAAAAAAAAAAA",
                            "AAAAAAAAAAAAAAAAAAAAAAAAAAAAAAAAAAAAAAA", "AAAAAAAAAAAAAAAAAAAAAAAAAAAAAAAAAAAAAAA",
                            "AAAAAAAAAAAAAAAAAAAAAAAAAAAAAAAAAAAAAAA", "AAAAAAAAAAAAAAAAAAAAAAAAAAAAAAAAAAAAAAA",
                            "AAAAAAAAAAAAAAAAAAAAAAAAAAAAAAAAAAAAAAA", "AAAAAAAAAAAAAAAAAAAAAAAAAAAAAAAAAAAAAAA",
                            "AAAAAAAAAAAAAAAAAAAAAAAAAAAAAAAAAAAAAAA", "AAAAAAAAAAAAAAAAAAAAAAAAAAAAAAAAAAAAAAA",
                            "AAAAAAAAAAAAAAAAAAAAAAAAAAAAAAAAAAAAAAA", "AAAAAAAAAAAAAAAAAAAAAAAAAAAAAAAAAAAAAAA",
                            "AAAAAAAAAAAAAAAAAAAAAAAAAAAAAAAAAAAAAAA", "AAAAAAAAAAAAAAAAAAAAAAAAAAAAAAAAAAAAAAA",
                            "AAAAAAAAAAAAAAAAAAAAAAAAAAAAAAAAAAAAAAA", "AAAAAAAAAAAAAAAAAAAAAAAAAAAAAAAAAAAAAAA",
                            "AAAAAAAAAAAAAAAAAAAAAAAAAAAAAAAAAAAAAAA", "AAAAAAAAAAAAAAAAAAAAAAAAAAAAAAAAAAAAAAA",
                            "AAAAAAAAAAAAAAAAAAAAAAAAAAAAAAAAAAAAAAA", "AAAAAAAAAAAAAAAAAAAHAAAAAAAAAAAAAAAAAAA",
                            "AAAAAAAAAAAAAAAABDABADBAAAAAAAAAAAAAAAA", "AAAAAAAAAAAAAAAAAAAAAAAAAAAAAAAAAAAAAAA",
                            "AAAAAAAAAAAAAAAAAAAAAAAAAAAAAAAAAAAAAAA", "AAAAAAAAAAAAAAAAAAAAAAAAAAAAAAAAAAAAAAA",
                            "AAAAAAAAAAAAAAAAAAAAAAAAAAAAAAAAAAAAAAA", "AAAAAAAAAAAAAAAAAAAAAAAAAAAAAAAAAAAAAAA",
                            "AAAAAAAAAAAAAAAAAAAAAAAAAAAAAAAAAAAAAAA", "AAAAAAAAAAAAAAAAAAAAAAAAAAAAAAAAAAAAAAA",
                            "AAAAAAAAAAAAAAAAAAAAAAAAAAAAAAAAAAAAAAA", "AAAAAAAAAAAAAAAAAAAAAAAAAAAAAAAAAAAAAAA",
                            "AAAAAAAAAAAAAAAAAAAAAAAAAAAAAAAAAAAAAAA", "AAAAAAAAAAAAAAAAAAAAAAAAAAAAAAAAAAAAAAA",
                            "AAAAAAAAAAAAAAAAAAAAAAAAAAAAAAAAAAAAAAA", "AAAAAAAAAAAAAAAAAAAAAAAAAAAAAAAAAAAAAAA",
                            "AAAAAAAAAAAAAAAAAAAAAAAAAAAAAAAAAAAAAAA", "AAAAAAAAAAAAAAAAAAAAAAAAAAAAAAAAAAAAAAA",
                            "AAAAAAAAAAAAAAAAAAAAAAAAAAAAAAAAAAAAAAA", "AAAAAAAAAAAAAAAAAAAAAAAAAAAAAAAAAAAAAAA",
                            "AAAAAAAAAAAAAAAAAAAAAAAAAAAAAAAAAAAAAAA", "AAAAAAAAAAAAAAAAAAAAAAAAAAAAAAAAAAAAAAA")
                    .where('H', controller(blocks(definition.getBlock())))
                    .where("A", Predicates.any())
                    .where('B', blocks(HIGH_ENERGY_COLLIDER_CASING.get()))
                    .where('E', blocks(QUANTUM_FIELD_STABILIZATION_CASING.get()))
                    .where('F', blocks(BATTERY_ULTIMATE_UXV.get()))
                    .where("G", blocks(ForgeRegistries.BLOCKS
                            .getValue(ResourceLocation.fromNamespaceAndPath(
                                    "gtceu",
                                    "neutronium_frame"))))
                    .where("D", blocks(ULTRA_DENSE_COLLIDER_CASING.get())
                            .or(Predicates.abilities(PartAbility.IMPORT_FLUIDS).setPreviewCount(1))
                            .or(Predicates.abilities(PartAbility.INPUT_LASER).setMaxGlobalLimited(1))
                            .or(Predicates.abilities(PartAbility.INPUT_ENERGY).setMaxGlobalLimited(2)
                                    .setMinGlobalLimited(1))
                            .or(Predicates.abilities(PartAbility.EXPORT_FLUIDS).setPreviewCount(1))
                            .or(Predicates.abilities(PartAbility.IMPORT_ITEMS).setPreviewCount(1))
                            .or(Predicates.abilities(PartAbility.EXPORT_ITEMS).setPreviewCount(1))
                            .or(autoAbilities(true, false, true)))
                    .build())
            .model(
                    createWorkableCasingMachineModel(
                            sogcore.id("block/casings/ultra_dense_collider_casing"),
                            sogcore.id("block/multiblock/high_energy_collider"))
                            .andThen(d -> d
                                    .addDynamicRenderer(
                                            SoGDynamicRenderHelpers::getPlasmaArcFurnaceRenderer)))
            .hasBER(true)
            .register();

    public static MachineDefinition[] registerTieredMachines(String name,
                                                             BiFunction<IMachineBlockEntity, Integer, MetaMachine> factory,
                                                             BiFunction<Integer, MachineBuilder<MachineDefinition, ?>, MachineDefinition> builder,
                                                             int... tiers) {
        MachineDefinition[] definitions = new MachineDefinition[GTValues.TIER_COUNT];
        for (int tier : tiers) {
            var register = REGISTRATE
                    .machine(GTValues.VN[tier].toLowerCase(Locale.ROOT) + "_" + name,
                            holder -> factory.apply(holder, tier))
                    .tier(tier);
            definitions[tier] = builder.apply(tier, register);
        }
        return definitions;
    }

    public static void init() {}
}
